Workbook

Sheet 기계코드
B2: system_code | C2: code_group | D2: code_key | E2: parent_key | F2: code_value | G2: code_value_en | H2: code_level | I2: is_leaf | J2: code_order | K2: iso15926_rdl | L2: description
B3: WAI_DESIGN_APP | C3: EQUIPMENT | D3: EQUIP | F3: 기계 | G3: Equipment | H3: 1 | J3: 1
B4: WAI_DESIGN_APP | C4: ELECTRIC_VALVE | D4: M_VALV | E4: EQUIP | F4: 자동 밸브 | G4: Automatic Valve | H4: 2 | J4: 1
B5: WAI_DESIGN_APP | C5: ELECTRIC_VALVE | D5: M_VAV01 | E5: M_VALV | F5: 게이트 밸브(슬루스 밸브) | G5: Gate Valve | H5: 3 | J5: 1
B6: WAI_DESIGN_APP | C6: ELECTRIC_VALVE | D6: M_VAV0101 | E6: M_VAV01 | F6: 전동식(1상식) 게이트 밸브(슬루스 밸브) | G6: Motorized 1-Phase Gate Valve | H6: 4 | I6: TRUE | J6: 1
B7: WAI_DESIGN_APP | C7: ELECTRIC_VALVE | D7: M_VAV0102 | E7: M_VAV01 | F7: 전동식(2상식) 게이트 밸브(슬루스 밸브) | G7: Motorized 2-Phase Gate Valve | H7: 4 | I7: TRUE | J7: 2
B8: WAI_DESIGN_APP | C8: ELECTRIC_VALVE | D8: M_VAV0103 | E8: M_VAV01 | F8: 유압식 게이트 밸브(슬루스 밸브) | G8: Hydraulic Gate Valve | H8: 4 | I8: TRUE | J8: 3
B9: WAI_DESIGN_APP | C9: ELECTRIC_VALVE | D9: M_VAV0104 | E9: M_VAV01 | F9: 공압식 게이트 밸브(슬루스 밸브) | G9: Pneumatic Gate Valve | H9: 4 | I9: TRUE | J9: 4
B10: WAI_DESIGN_APP | C10: ELECTRIC_VALVE | D10: M_VAV0105 | E10: M_VAV01 | F10: 전동식 나이프 게이트 밸브 | G10: Motorized Knife Gate Valve | H10: 4 | I10: TRUE | J10: 5
B11: WAI_DESIGN_APP | C11: ELECTRIC_VALVE | D11: M_VAV02 | E11: M_VALV | F11: 버터플라이밸브 | G11: Butterfly Valve | H11: 3 | J11: 2
B12: WAI_DESIGN_APP | C12: ELECTRIC_VALVE | D12: M_VAV0201 | E12: M_VAV02 | F12: 전동식(1상식) 버터플라이 밸브 | G12: Motorized 1-Phase Butterfly Valve | H12: 4 | I12: TRUE | J12: 1
B13: WAI_DESIGN_APP | C13: ELECTRIC_VALVE | D13: M_VAV0202 | E13: M_VAV02 | F13: 전동식(2상식) 버터플라이 밸브 | G13: Motorized 2-Phase Butterfly Valve | H13: 4 | I13: TRUE | J13: 2
B14: WAI_DESIGN_APP | C14: ELECTRIC_VALVE | D14: M_VAV0203 | E14: M_VAV02 | F14: 유압식 버터플라이 밸브 | G14: Hydraulic Butterfly Valve | H14: 4 | I14: TRUE | J14: 3
B15: WAI_DESIGN_APP | C15: ELECTRIC_VALVE | D15: M_VAV0204 | E15: M_VAV02 | F15: 공압식 버터플라이 밸브 | G15: Pneumatic Butterfly Valve | H15: 4 | I15: TRUE | J15: 4
B16: WAI_DESIGN_APP | C16: ELECTRIC_VALVE | D16: M_VAV0205 | E16: M_VAV02 | F16: 공압식 버터플라이 컨트롤밸브 | G16: Pneumatic Butterfly Control Valve | H16: 4 | I16: TRUE | J16: 5
B17: WAI_DESIGN_APP | C17: ELECTRIC_VALVE | D17: M_VAV03 | E17: M_VALV | F17: 체크밸브 | G17: Check Valve | H17: 3 | J17: 3
B18: WAI_DESIGN_APP | C18: ELECTRIC_VALVE | D18: M_VAV0301 | E18: M_VAV03 | F18: 전동식(1상식) 체크 밸브 | G18: Motorized 1-Phase Check Valve | H18: 4 | I18: TRUE | J18: 1
B19: WAI_DESIGN_APP | C19: ELECTRIC_VALVE | D19: M_VAV0302 | E19: M_VAV03 | F19: 전동식(2상식) 체크 밸브 | G19: Motorized 2-Phase Check Valve | H19: 4 | I19: TRUE | J19: 2
B20: WAI_DESIGN_APP | C20: ELECTRIC_VALVE | D20: M_VAV0303 | E20: M_VAV03 | F20: 유압식 체크 밸브 | G20: Hydraulic Check Valve | H20: 4 | I20: TRUE | J20: 3
B21: WAI_DESIGN_APP | C21: ELECTRIC_VALVE | D21: M_VAV0304 | E21: M_VAV03 | F21: 공압식 체크 밸브 | G21: Pneumatic Check Valve | H21: 4 | I21: TRUE | J21: 4
B22: WAI_DESIGN_APP | C22: ELECTRIC_VALVE | D22: M_VAV04 | E22: M_VALV | F22: 볼밸브 | G22: Ball Valve | H22: 3 | J22: 4
B23: WAI_DESIGN_APP | C23: ELECTRIC_VALVE | D23: M_VAV0401 | E23: M_VAV04 | F23: 전동식(1상식) 볼 밸브 | G23: Motorized 1-Phase Ball Valve | H23: 4 | I23: TRUE | J23: 1
B24: WAI_DESIGN_APP | C24: ELECTRIC_VALVE | D24: M_VAV0402 | E24: M_VAV04 | F24: 전동식(2상식) 볼 밸브 | G24: Motorized 2-Phase Ball Valve | H24: 4 | I24: TRUE | J24: 2
B25: WAI_DESIGN_APP | C25: ELECTRIC_VALVE | D25: M_VAV0403 | E25: M_VAV04 | F25: 유압식 볼 밸브 | G25: Hydraulic Ball Valve | H25: 4 | I25: TRUE | J25: 3
B26: WAI_DESIGN_APP | C26: ELECTRIC_VALVE | D26: M_VAV0404 | E26: M_VAV04 | F26: 공압식 볼 밸브 | G26: Pneumatic Ball Valve | H26: 4 | I26: TRUE | J26: 4
B27: WAI_DESIGN_APP | C27: ELECTRIC_VALVE | D27: M_VAV05 | E27: M_VALV | F27: 다이아프램밸브 | G27: Diaphragm Valve | H27: 3 | J27: 5
B28: WAI_DESIGN_APP | C28: ELECTRIC_VALVE | D28: M_VAV0501 | E28: M_VAV05 | F28: 전동식(1상식) 다이아프램밸브 밸브 | G28: Motorized 1-Phase Diaphragm Valve | H28: 4 | I28: TRUE | J28: 1
B29: WAI_DESIGN_APP | C29: ELECTRIC_VALVE | D29: M_VAV0502 | E29: M_VAV05 | F29: 전동식(2상식) 다이아프램밸브 밸브 | G29: Motorized 2-Phase Diaphragm Valve | H29: 4 | I29: TRUE | J29: 2
B30: WAI_DESIGN_APP | C30: ELECTRIC_VALVE | D30: M_VAV0503 | E30: M_VAV05 | F30: 유압식 다이아프램밸브 밸브 | G30: Hydraulic Diaphragm Valve | H30: 4 | I30: TRUE | J30: 3
B31: WAI_DESIGN_APP | C31: ELECTRIC_VALVE | D31: M_VAV0504 | E31: M_VAV05 | F31: 공압식 다이아프램밸브 밸브 | G31: Pneumatic Diaphragm Valve | H31: 4 | I31: TRUE | J31: 4
B32: WAI_DESIGN_APP | C32: ELECTRIC_VALVE | D32: M_VAV06 | E32: M_VALV | F32: 글로우버밸브 | G32: Globe Valve | H32: 3 | J32: 6
B33: WAI_DESIGN_APP | C33: ELECTRIC_VALVE | D33: M_VAV0601 | E33: M_VAV06 | F33: 전동식(1상식) 글로우버 밸브 | G33: Motorized 1-Phase Globe Valve | H33: 4 | I33: TRUE | J33: 1
B34: WAI_DESIGN_APP | C34: ELECTRIC_VALVE | D34: M_VAV0602 | E34: M_VAV06 | F34: 전동식(2상식) 글로우버 밸브 | G34: Motorized 2-Phase Globe Valve | H34: 4 | I34: TRUE | J34: 2
B35: WAI_DESIGN_APP | C35: ELECTRIC_VALVE | D35: M_VAV0603 | E35: M_VAV06 | F35: 유압식 글로우버 밸브 | G35: Hydraulic Globe Valve | H35: 4 | I35: TRUE | J35: 3
B36: WAI_DESIGN_APP | C36: ELECTRIC_VALVE | D36: M_VAV0604 | E36: M_VAV06 | F36: 공압식 글로우버 밸브 | G36: Pneumatic Globe Valve | H36: 4 | I36: TRUE | J36: 4
B37: WAI_DESIGN_APP | C37: ELECTRIC_VALVE | D37: M_VAV07 | E37: M_VALV | F37: 자동제어밸브 | G37: Control Valve | H37: 3 | J37: 7
B38: WAI_DESIGN_APP | C38: ELECTRIC_VALVE | D38: M_VAV0701 | E38: M_VAV07 | F38: 감압밸브 | G38: Pressure Reducing Valve | H38: 4 | I38: TRUE | J38: 1
B39: WAI_DESIGN_APP | C39: ELECTRIC_VALVE | D39: M_VAV0702 | E39: M_VAV07 | F39: 차압밸브 | G39: Differential Pressure Valve | H39: 4 | I39: TRUE | J39: 2
B40: WAI_DESIGN_APP | C40: ELECTRIC_VALVE | D40: M_VAV0703 | E40: M_VAV07 | F40: 밸런싱밸브 | G40: Balancing Valve | H40: 4 | I40: TRUE | J40: 3
B41: WAI_DESIGN_APP | C41: ELECTRIC_VALVE | D41: M_VAV0704 | E41: M_VAV07 | F41: 수위조절밸브 | G41: Level Control Valve | H41: 4 | I41: TRUE | J41: 4
...

Sheet 기자재코드
C2: 그룹코드 | D2: 코드 | E2: 부모코드 | F2: 코드값명(국문명) | G2: 코드값명(영문명) | H2: 레벨 | I2: 순서
C3: ARTEFACT | D3: ARTF | F3: 기자재 | G3: Artefact | H3: 1
C4: EQUIP_PARTS | D4: EQP_PTS | E4: ARTF | F4: 기계 부품 | G4: Equipment Parts | H4: 2 | I4: 1
C5: EQUIP_PARTS | D5: P_MOTR | E5: EQP_PTS | F5: 펌프 모터 | G5: Pump Motor | H5: 3 | I5: 1
C6: EQUIP_PARTS | D6: P_MOT01 | E6: P_MOTR | F6: 유도전동기(삼성전폐) | G6: 유도전동기(삼성전폐) | H6: 4 | I6: 1
C7: EQUIP_PARTS | D7: P_MOT02 | E7: P_MOTR | F7: 유도전동기(삼성반폐) | G7: 유도전동기(삼성반폐) | H7: 4 | I7: 2
C8: EQUIP_PARTS | D8: P_MOT99 | E8: P_MOTR | F8: 기타 펌프모터 | G8: Other Types of Pump Motors | H8: 4 | I8: 3
C9: EQUIP_PARTS | D9: S_VALV | E9: EQP_PTS | F9: 밸브 실링 | G9: Valve Sealing | H9: 3 | I9: 2
C10: EQUIP_PARTS | D10: S_VAV01 | E10: E_VAV_SL | F10: 고무 시트(EPDM) | G10: EPDM Seat | H10: 4 | I10: 1
C11: EQUIP_PARTS | D11: S_VAV02 | E11: E_VAV_SL | F11: 메탈 시트 | G11: Metal Seat | H11: 4 | I11: 2
C12: EQUIP_PARTS | D12: S_VAV03 | E12: E_VAV_SL | F12: 더블 디스크 | G12: Double Disk | H12: 4 | I12: 3
C13: EQUIP_PARTS | D13: S_VAV04 | E13: E_VAV_SL | F13: 플렉서블 웻지 디스크 | G13: Flexible Wedge Disk | H13: 4 | I13: 4
C14: EQUIP_PARTS | D14: S_VAV05 | E14: E_VAV_SL | F14: 분리형 디스크 | G14: Split Disk | H14: 4 | I14: 5
C15: EQUIP_PARTS | D15: S_VAV99 | E15: E_VAV_SL | F15: 기타 씰링 | G15: Other Types of Sealing | H15: 4 | I15: 6
... C31: EQUIP_PARTS | D31: S_SYS99 | E31: S_SYST | F31: 기타 기동방식 | G31: Other Types of Starting Method | H31: 4 | I31: 5

Sheet 재질코드
B2: system_code | C2: code_group | D2: code_key | E2: parent_key | F2: code_value | G2: code_value_en | H2: code_level | I2: is_leaf | J2: code_order | K2: iso15926_rdl | L2: description
B3: WAI_DESIGN_APP | C3: MATERIALS | D3: MATER | F3: 재질 | G3: Materials | H3: 1 | J3: 1
B4: WAI_DESIGN_APP | C4: MATERIALS_KS | D4: MATER_KS | E4: MATER | F4: 한국규격(KS)에 의한 표시기호 | G4: 한국규격(KS)에 의한 표시기호 | H4: 2 | J4: 1
B5: WAI_DESIGN_APP | C5: MATERIALS_KS | D5: GCD | E5: MATER_KS | F5: 구상흑연주철(GCD) | G5: Graphite Casting Ductile | H5: 3 | J5: 1
B6: WAI_DESIGN_APP | C6: MATERIALS_KS | D6: GCD450 | E6: GCD | F6: GCD450 | G6: Graphite Casting Ductile(450) | H6: 4 | I6: YES | J6: 1 | M6: 밸브
B7: WAI_DESIGN_APP | C7: MATERIALS_KS | D7: SCPH | E7: MATER_KS | F7: 고온고압용 주강(SCPH) | G7: Steel Casting Pressure High Temperature | H7: 3 | J7: 2
B8: WAI_DESIGN_APP | C8: MATERIALS_KS | D8: SCPH2 | E8: SCPH | F8: SCPH2 | G8: Steel Casting Pressure High Temperature(2) | H8: 4 | I8: YES | J8: 1 | M8: 밸브
B9: WAI_DESIGN_APP | C9: MATERIALS_KS | D9: SSC | E9: MATER_KS | F9: 스테인리스 주강(SSC) | G9: Steel Casting Stainless | H9: 3 | J9: 3 | L9: 주로 SCS로 표시하며 JIS에서도 사용
B10: WAI_DESIGN_APP | C10: MATERIALS_KS | D10: SSC13 | E10: MATER | F10: SSC13 | G10: Steel Casting Stainless(13) | H10: 4 | I10: YES | J10: 1 | M10: 밸브, 스프르트펌프
B11: WAI_DESIGN_APP | C11: MATERIALS_KS | D11: STEEL_FORGING | E11: MATER_KS | F11: 탄소강 단강(SF) | G11: Carbon Steel Forgings | H11: 3 | J11: 4
B12: WAI_DESIGN_APP | C12: MATERIALS_KS | D12: SF440A | E12: STEEL_FORGING | F12: SF440A | G12: Carbon Steel Forgings(440A) | H12: 4 | I12: YES | J12: 1 | M12: 밸브
B13: WAI_DESIGN_APP | C13: MATERIALS_KS | D13: GRAY_CAST | E13: MATER_KS | F13: 회주철(GC) | G13: Gray Cast Iron | H13: 3 | J13: 5
B14: WAI_DESIGN_APP | C14: MATERIALS_KS | D14: GC200 | E14: MATER | F14: GC200 | G14: Gray Cast Iron(200) | H14: 4 | I14: YES | J14: 1 | M14: 스프르트펌프
B15: WAI_DESIGN_APP | C15: MATERIALS_KS | D15: GC250 | E15: MATER | F15: GC250 | G15: Gray Cast Iron(250) | H15: 4 | I15: YES | J15: 2 | M15: 일축스크류(모노)펌프
B16: WAI_DESIGN_APP | C16: MATERIALS_KS | D16: STEEL_MACH_C | E16: MATER_KS | F16: 기계 구조용 탄소 강재(SM) | G16: Steel Machine Carbon | H16: 3 | J16: 6
B17: WAI_DESIGN_APP | C17: MATERIALS_KS | D17: SM45C | E17: STEEL_MACH_C | F17: SM45C | G17: Steel Machine Carbon(45) | H17: 4 | I17: YES | J17: 1 | M17: 모노펌프부품
B18: WAI_DESIGN_APP | C18: MATERIALS_KS | D18: SNCM | E18: MATER_KS | F18: 니켈 크롬 몰리브덴강(SNCM) | G18: Steel Nickel Chromium Molybdenum | H18: 3 | J18: 7
B19: WAI_DESIGN_APP | C19: MATERIALS_KS | D19: SNCM21 | E19: SNCM | F19: SNCM21 | G19: Steel Nickel Chromium Molybdenum(21) | H19: 4 | I19: YES | J19: 1 | M19: 모노펌프부품
B20: WAI_DESIGN_APP | C20: MATERIALS_KS | D20: STD | E20: MATER_KS | F20: 합금공구강(STD) | G20: Steel Tool Dies | H20: 3 | J20: 8
B21: WAI_DESIGN_APP | C21: MATERIALS_KS | D21: STD11 | E21: STD | F21: STD11 | G21: Steel Tool Dies(11) | H21: 4 | I21: YES | J21: 1 | M21: 모노펌프부품
B22: WAI_DESIGN_APP | C22: MATERIALS_KS | D22: STD11_STS304 | E22: STD | F22: STD11/STS304 | G22: STD11/STS304 | H22: 4 | I22: YES | J22: 2 | M22: 모노펌프부품
B23: WAI_DESIGN_APP | C23: MATERIALS_KS | D23: STAINLESS_STEEL | E23: MATER_KS | F23: 스테인리스강(STS) | G23: Stainless Steel | H23: 3 | J23: 9
B24: WAI_DESIGN_APP | C24: MATERIALS_KS | D24: STS304 | E24: STAINLESS_STEEL | F24: STS304 | G24: Stainless Steel(304) | H24: 4 | I24: YES | J24: 1 | M24: 모노펌프부품
B25: WAI_DESIGN_APP | C25: MATERIALS_KS | D25: STS304_HCr | E25: STAINLESS_STEEL | F25: STS304 고크롬 | G25: Stainless Steel(304) High Chromium | H25: 4 | I25: YES | J25: 2 | M25: 모노펌프부품
B26: WAI_DESIGN_APP | C26: MATERIALS_KS | D26: STS316 | E26: STAINLESS_STEEL | F26: STS316 몰리브덴 | G26: Stainless Steel(316) Molybdenum | H26: 4 | I26: YES | J26: 3 | M26: 모노펌프부품
B27: WAI_DESIGN_APP | C27: MATERIALS_RUBBER | D27: MATER_RUBBER | E27: MATER | F27: 고무 표시기호 | G27: Rubber | H27: 2 | J27: 2
B28: WAI_DESIGN_APP | C28: MATERIALS | D28: NBR | E28: MATER_RUBBER | F28: 니트릴 고무(NBR) | G28: Nitrile Butadiene Rubber | H28: 3 | I28: YES | J28: 1 | M28: 모노펌프부품
B29: WAI_DESIGN_APP | C29: MATERIALS | D29: NBR_EPDM | E29: MATER_RUBBER | F29: NBR/EPDM | G29: NBR/EPDM | H29: 3 | I29: YES | J29: 2 | M29: 모노펌프부품
B30: WAI_DESIGN_APP | C30: MATERIALS | D30: EPDM | E30: MATER_RUBBER | F30: 에틸렌 프로필렌 고무(EPDM) | G30: Ethylene Propylene Diene Monomer | H30: 3 | I30: YES | J30: 3 | M30: 모노펌프부품
B31: WAI_DESIGN_APP | C31: MATERIALS | D31: FKM | E31: MATER_RUBBER | F31: 불소화 엘라스토머(FKM) | G31: Fluoropolymer | H31: 3 | J31: 4
B32: WAI_DESIGN_APP | C32: MATERIALS | D32: VITON | E32: FKM | F32: Viton™ | G32: Viton™ | H32: 4 | I32: YES | J32: 1 | L32: 듀퐁사 브랜드 | M32: 모노펌프부품
B33: WAI_DESIGN_APP | C33: MATERIALS_PLASTIC | D33: MATER_PLASTIC | E33: MATER | F33: 플라스틱 표시기호 | G33: Plastic | H33: 2 | J33: 3
B34: WAI_DESIGN_APP | C34: MATERIALS | D34: PP | E34: MATER_PLASTIC | F34: 폴리프로필렌(PP) | G34: Polypropylene | H34: 3 | I34: YES | J34: 1 | M34: 다이아프램펌프
B35: WAI_DESIGN_APP | C35: MATERIALS | D35: PVDF | E35: MATER_PLASTIC | F35: 폴리비닐리덴 플루오라이드(PVDF) | G35: Polyvinylidene Fluoride | H35: 3 | I35: YES | J35: 2 | M35: 다이아프램펌프
B36: WAI_DESIGN_APP | C36: MATERIALS_JIS | D36: MATER_JIS | E36: MATER | F36: 일본규격(JIS)에 의한 표시기호 | G36: 일본규격(JIS)에 의한 표시기호 | H36: 2 | J36: 4
B37: WAI_DESIGN_APP | C37: MATERIALS_JIS | D37: SKD | E37: MATER_JIS | F37: 합금공구강(SKD) | G37: Steel Kougu Dice(SKD) | H37: 3 | J37: 1 | L37: KS규격 STD11과 매우 유사 | M37: 모노펌프부품
B38: WAI_DESIGN_APP | C38: MATERIALS_JIS | D38: SKD11 | E38: MATER_JIS | F38: SKD11 | G38: SKD11 | H38: 4 | I38: YES | J38: 1 | L38: KS규격 STD11과 매우 유사
B39: WAI_DESIGN_APP | C39: MATERIALS_JIS | F39: 스테인리스강(SUS) | G39: Steel Use Stainless(SUS) | H39: 3
B40: WAI_DESIGN_APP | C40: MATERIALS_JIS | D40: STS304 | E40: STAINLESS_STEEL | F40: SUS304 | G40: Stainless Steel(304) | H40: 4 | I40: YES | J40: 1 | L40: KS규격 STS304와 동일 | M40: 모노펌프부품
B41: WAI_DESIGN_APP | C41: MATERIALS | D41: MOB99 | E41: MATER | F41: 기타 재질 | G41: Other Types of Materials | H41: 2 | J41: 5

Sheet 공급업체코드
B2: vendor_id | C2: vendor_name_en | D2: vendor_name_kr
B3: VM_0000 | C3: Non-designated company | D3: 미지정업체
B4: VM_BKT | C4: BKT | D4: (주)부강테크
B5: VM_BKT_SJ | C5: BKT/SJ | D5: (주)부강테크/삼진
B6: VM_BKT_CD_VM | C6: BKT/CS | D6: (주)부강테크/창신
B7: VM_BKT_TM | C7: BKT/TM | D7: (주)부강테크/터보맥스
B8: VM_BKT_HS | C8: BKT/HS | D8: (주)부강테크/한신테크노
B9: VM_HDHD_ELC | C9: HD Hyundai electric | D9: HD현대일렉트릭
B10: VM_LS_ELC | C10: LS ELECTRIC | D10: LS ELECTRIC
B11: VM_KB_ELC | C11: KyuongBo Electric | D11: 경보전기
B12: VM_KW_COMP | C12: Kyungwon Compressor | D12: 경원콤프레샤
B13: VM_KJ_IND | C13: Kyungjin Industrial | D13: 경진산업
... B51: VM_SJ_MTEC | C51: Sungjin M-Tec Co., Ltd | D51: 성진엠텍
A52: 260312 | B52: VM_DB_ENG | C52: DAI BONG ENGINEERING | D52: (주)대봉엔지니어링
B53: VM_DY_BLR | C53: DAEYEOL BOILER Co,. Ltd | D53: (주)대열보일러
B54: VM_TSNTEC | C54: TSNTEC Co., Ltd | D54: (주)티에스엔텍
B55: VM_WILO | C55: Wilo Pumps Ltd. | D55: 윌로펌프(주)
B56: VM_DH_GEN | C56: DAEHAN GENERATOR Co., Ltd. | D56: 대한발전기(주)

Sheet 열반응기
B1: 장비코드 | D1: 장비유형 | F1: 공급업체명 | G1: 모델명 | H1: 용량(㎥) | I1: 수량 | J1: 단위 | K1: 호표(1) | L1: 분류 | M1: 단가(원) | N1: 견적가(원) | O1: 단가출처 | P1: 사용여부 | Q1: 장비설명 | R1: 단위시스템코드
B2: equipment_code | C2: 작업용 필드 | D2: equipment_type | E2: 작업용 필드 | F2: vendor_id | G2: model_number | H2: i_capacity_m3 | I2: i_no_EA | J2: s_unit_NONE | K2: s_primary_item_no_NONE | L2: s_remark_NONE | M2: o_unit_price_KRW | N2: o_invoice_price_KRW | O2: o_price_reference | P2: is_active | Q2: description | R2: unit_system_code
B3: =D3&"_"&F3&"_"&H3&"_"&I3 -> M_THM0101_VM_BKT_2_2 | C3: =기계코드!F260 -> 열가수분해설비(D2-2) | D3: {=INDEX(기계코드!$D$4:$D$1022,MATCH(1,(C3=기계코드!$F$4:$F$1022)*1,0))} -> M_THM0101 | E3: (주)부강테크 | F3: {=INDEX(공급업체코드!$B$3:$B$1000,MATCH(1,(E3=공급업체코드!$D$3:$D$1000)*1,0))} -> VM_BKT | G3: =C3 -> 열가수분해설비(D2-2) | H3: 2 | I3: 2 | J3: 식 | L3: 공법 | M3: 999 | O3: 견적가 | P3: TRUE
B4: =D4&"_"&F4&"_"&H4&"_"&I4 -> M_THM0102_VM_BKT_2_3 | C4: =기계코드!F261 -> 열가수분해설비(D2-3) | D4: {=INDEX(기계코드!$D$4:$D$1022,MATCH(1,(C4=기계코드!$F$4:$F$1022)*1,0))} -> M_THM0102 | E4: (주)부강테크 | F4: {=INDEX(공급업체코드!$B$3:$B$1000,MATCH(1,(E4=공급업체코드!$D$3:$D$1000)*1,0))} -> VM_BKT | G4: =C4 -> 열가수분해설비(D2-3) | H4: 2 | I4: 3 | J4: 식 | L4: 공법 | M4: 999 | O4: 견적가 | P4: TRUE
B5: =D5&"_"&F5&"_"&H5&"_"&I5 -> M_THM0103_VM_BKT_2_4 | C5: =기계코드!F262 -> 열가수분해설비(D2-4) | D5: {=INDEX(기계코드!$D$4:$D$1022,MATCH(1,(C5=기계코드!$F$4:$F$1022)*1,0))} -> M_THM0103 | E5: (주)부강테크 | F5: {=INDEX(공급업체코드!$B$3:$B$1000,MATCH(1,(E5=공급업체코드!$D$3:$D$1000)*1,0))} -> VM_BKT | G5: =C5 -> 열가수분해설비(D2-4) | H5: 2 | I5: 4 | J5: 식 | L5: 공법 | M5: 999 | O5: 견적가 | P5: TRUE
B6: =D6&"_"&F6&"_"&H6&"_"&I6 -> M_THM0104_VM_BKT_3_3 | C6: =기계코드!F263 -> 열가수분해설비(D3-3) | D6: {=INDEX(기계코드!$D$4:$D$1022,MATCH(1,(C6=기계코드!$F$4:$F$1022)*1,0))} -> M_THM0104 | E6: (주)부강테크 | F6: {=INDEX(공급업체코드!$B$3:$B$1000,MATCH(1,(E6=공급업체코드!$D$3:$D$1000)*1,0))} -> VM_BKT | G6: =C6 -> 열가수분해설비(D3-3) | H6: 3 | I6: 3 | J6: 식 | L6: 공법 | M6: 999 | O6: 견적가 | P6: TRUE
B7: =D7&"_"&F7&"_"&H7&"_"&I7 -> M_THM0105_VM_BKT_3_4 | C7: =기계코드!F264 -> 열가수분해설비(D3-4) | D7: {=INDEX(기계코드!$D$4:$D$1022,MATCH(1,(C7=기계코드!$F$4:$F$1022)*1,0))} -> M_THM0105 | E7: (주)부강테크 | F7: {=INDEX(공급업체코드!$B$3:$B$1000,MATCH(1,(E7=공급업체코드!$D$3:$D$1000)*1,0))} -> VM_BKT | G7: =C7 -> 열가수분해설비(D3-4) | H7: 3 | I7: 4 | J7: 식 | L7: 공법 | M7: 999 | O7: 견적가 | P7: TRUE
B8: =D8&"_"&F8&"_"&H8&"_"&I8 -> M_THM0106_VM_BKT_6_3 | C8: =기계코드!F265 -> 열가수분해설비(D6-3) | D8: {=INDEX(기계코드!$D$4:$D$1022,MATCH(1,(C8=기계코드!$F$4:$F$1022)*1,0))} -> M_THM0106 | E8: (주)부강테크 | F8: {=INDEX(공급업체코드!$B$3:$B$1000,MATCH(1,(E8=공급업체코드!$D$3:$D$1000)*1,0))} -> VM_BKT | G8: =C8 -> 열가수분해설비(D6-3) | H8: 6 | I8: 3 | J8: 식 | L8: 공법 | M8: 999 | O8: 견적가 | P8: TRUE
B9: =D9&"_"&F9&"_"&H9&"_"&I9 -> M_THM0107_VM_BKT_6_4 | C9: =기계코드!F266 -> 열가수분해설비(D6-4) | D9: {=INDEX(기계코드!$D$4:$D$1022,MATCH(1,(C9=기계코드!$F$4:$F$1022)*1,0))} -> M_THM0107 | E9: (주)부강테크 | F9: {=INDEX(공급업체코드!$B$3:$B$1000,MATCH(1,(E9=공급업체코드!$D$3:$D$1000)*1,0))} -> VM_BKT | G9: =C9 -> 열가수분해설비(D6-4) | H9: 6 | I9: 4 | J9: 식 | L9: 공법 | M9: 999 | O9: 견적가 | P9: TRUE
B10: =D10&"_"&F10&"_"&H10&"_"&I10 -> M_THM0108_VM_BKT_9_3 | C10: =기계코드!F267 -> 열가수분해설비(D9-3) | D10: {=INDEX(기계코드!$D$4:$D$1022,MATCH(1,(C10=기계코드!$F$4:$F$1022)*1,0))} -> M_THM0108 | E10: (주)부강테크 | F10: {=INDEX(공급업체코드!$B$3:$B$1000,MATCH(1,(E10=공급업체코드!$D$3:$D$1000)*1,0))} -> VM_BKT | G10: =C10 -> 열가수분해설비(D9-3) | H10: 9 | I10: 3 | J10: 식 | L10: 공법 | M10: 999 | O10: 견적가 | P10: TRUE
B11: =D11&"_"&F11&"_"&H11&"_"&I11 -> M_THM0109_VM_BKT_9_4 | C11: =기계코드!F268 -> 열가수분해설비(D9-4) | D11: {=INDEX(기계코드!$D$4:$D$1022,MATCH(1,(C11=기계코드!$F$4:$F$1022)*1,0))} -> M_THM0109 | E11: (주)부강테크 | F11: {=INDEX(공급업체코드!$B$3:$B$1000,MATCH(1,(E11=공급업체코드!$D$3:$D$1000)*1,0))} -> VM_BKT | G11: =C11 -> 열가수분해설비(D9-4) | H11: 9 | I11: 4 | J11: 식 | L11: 공법 | M11: 999 | O11: 견적가 | P11: TRUE
B12: =D12&"_"&F12&"_"&H12&"_"&I12 -> M_THM0110_VM_BKT_12_4 | C12: =기계코드!F269 -> 열가수분해설비(D12-4) | D12: {=INDEX(기계코드!$D$4:$D$1022,MATCH(1,(C12=기계코드!$F$4:$F$1022)*1,0))} -> M_THM0110 | E12: (주)부강테크 | F12: {=INDEX(공급업체코드!$B$3:$B$1000,MATCH(1,(E12=공급업체코드!$D$3:$D$1000)*1,0))} -> VM_BKT | G12: =C12 -> 열가수분해설비(D12-4) | H12: 12 | I12: 4 | J12: 식 | L12: 공법 | M12: 999 | O12: 견적가 | P12: TRUE
B14: =D14&"_"&F14&"_"&H14&"_"&I14 -> M_THM0201_VM_BKT_2_2 | C14: =기계코드!F271 -> 수열탄화설비(2D-2) | D14: {=INDEX(기계코드!$D$4:$D$1022,MATCH(1,(C14=기계코드!$F$4:$F$1022)*1,0))} -> M_THM0201 | E14: (주)부강테크 | F14: {=INDEX(공급업체코드!$B$3:$B$1000,MATCH(1,(E14=공급업체코드!$D$3:$D$1000)*1,0))} -> VM_BKT | G14: =C14 -> 수열탄화설비(2D-2) | H14: 2 | I14: 2 | J14: 식 | L14: 공법 | M14: 999 | O14: 견적가 | P14: TRUE
B15: =D15&"_"&F15&"_"&H15&"_"&I15 -> M_THM0202_VM_BKT_2_3 | C15: =기계코드!F272 -> 수열탄화설비(2D-3) | D15: {=INDEX(기계코드!$D$4:$D$1022,MATCH(1,(C15=기계코드!$F$4:$F$1022)*1,0))} -> M_THM0202 | E15: (주)부강테크 | F15: {=INDEX(공급업체코드!$B$3:$B$1000,MATCH(1,(E15=공급업체코드!$D$3:$D$1000)*1,0))} -> VM_BKT | G15: =C15 -> 수열탄화설비(2D-3) | H15: 2 | I15: 3 | J15: 식 | L15: 공법 | M15: 999 | O15: 견적가 | P15: TRUE
... B23: =D23&"_"&F23&"_"&H23&"_"&I23 -> M_THM0210_VM_BKT_12_4 | C23: =기계코드!F280 -> 수열탄화설비(12D-4) | D23: {=INDEX(기계코드!$D$4:$D$1022,MATCH(1,(C23=기계코드!$F$4:$F$1022)*1,0))} -> M_THM0210 | E23: (주)부강테크 | F23: {=INDEX(공급업체코드!$B$3:$B$1000,MATCH(1,(E23=공급업체코드!$D$3:$D$1000)*1,0))} -> VM_BKT | G23: =C23 -> 수열탄화설비(12D-4) | H23: 12 | I23: 4 | J23: 식 | L23: 공법 | M23: 999 | O23: 견적가 | P23: TRUE

Sheet 보일러
B1: 장비코드 | D1: 장비유형 | F1: 공급업체명 | G1: 모델명 | H1: 열량(kcal/hr) | I1: 용량(kg/h) | J1: 동력(kW) | K1: 기동방식 | L1: 정격전압(V) | M1: 효율(%) | N1: 역률(%) | O1: 수용율(%) | P1: 총중량(kg) | Q1: 단위 | R1: 호표(1) | S1: 분류 | T1: 단가(원) | U1: 견적가(원) | V1: 단가출처 | W1: 사용여부 | X1: 장비설명 | Y1: 단위시스템코드
B2: equipment_code | C2: 작업용 필드 | D2: equipment_type | E2: 작업용 필드 | F2: vendor_id | G2: model_number | H2: i_calorie_kcal_h | I2: i_capacity_kg_h | J2: s_power_kW | K2: s_ctrl_method | L2: s_rated_volt_V | M2: s_efficiency_percent | N2: s_pwr_factor_percent | O2: s_demand_factor_percent | P2: s_total_wgt_kg | Q2: s_unit_NONE | R2: s_primary_item_no_NONE | S2: s_remark_NONE | T2: o_unit_price_KRW | U2: o_invoice_price_KRW | V2: o_price_reference | W2: is_active | X2: description | Y2: unit_system_code
B3: =D3&"_"&F3&"_"&G3&"_"&I3 -> M_BLR0101_VM_DY_BLR_DMXR-100PG_1000 | C3: 노통연관식 증기 보일러 (가스) | D3: {=INDEX(기계코드!$D$4:$D$1022,MATCH(1,(C3=기계코드!$F$4:$F$1022)*1,0))} -> M_BLR0101 | E3: (주)대열보일러 | F3: {=INDEX(공급업체코드!$B$3:$B$1000,MATCH(1,(E3=공급업체코드!$D$3:$D$1000)*1,0))} -> VM_DY_BLR | G3: ="DMXR-"&LEFT(I3,3)&"PG" -> DMXR-100PG | I3: 1000 | J3: =2.2*2+3.7 -> 8.1 | K3: S_SYS04 | L3: 380 | M3: 0.99 | N3: 0.9 | O3: 90 | P3: 6600 | Q3: 식 | T3: 125900000 | V3: 물가자료26년4월호908Page | W3: TRUE | X3: 초저녹스 고효율 콘덴싱 보일러
B4: =D4&"_"&F4&"_"&G4&"_"&I4 -> M_BLR0101_VM_DY_BLR_DMXR-150PG_1500 | C4: 노통연관식 증기 보일러 (가스) | D4: {=INDEX(기계코드!$D$4:$D$1022,MATCH(1,(C4=기계코드!$F$4:$F$1022)*1,0))} -> M_BLR0101 | E4: (주)대열보일러 | F4: {=INDEX(공급업체코드!$B$3:$B$1000,MATCH(1,(E4=공급업체코드!$D$3:$D$1000)*1,0))} -> VM_DY_BLR | G4: ="DMXR-"&LEFT(I4,3)&"PG" -> DMXR-150PG | I4: 1500 | J4: =2.2*2+5.5 -> 9.9 | K4: S_SYS04 | L4: 380 | M4: 0.99 | N4: 0.9 | O4: 90 | P4: 7600 | Q4: 식 | T4: 136400000 | V4: 물가자료26년4월호908Page | W4: TRUE | X4: 초저녹스 고효율 콘덴싱 보일러
B5: =D5&"_"&F5&"_"&G5&"_"&I5 -> M_BLR0101_VM_DY_BLR_DMXR-200PG_2000 | C5: 노통연관식 증기 보일러 (가스) | D5: {=INDEX(기계코드!$D$4:$D$1022,MATCH(1,(C5=기계코드!$F$4:$F$1022)*1,0))} -> M_BLR0101 | E5: (주)대열보일러 | F5: {=INDEX(공급업체코드!$B$3:$B$1000,MATCH(1,(E5=공급업체코드!$D$3:$D$1000)*1,0))} -> VM_DY_BLR | G5: ="DMXR-"&LEFT(I5,3)&"PG" -> DMXR-200PG | I5: 2000 | J5: =3*2+11 -> 17 | K5: S_SYS04 | L5: 380 | M5: 0.99 | N5: 0.9 | O5: 90 | P5: 8200 | Q5: 식 | T5: 155400000 | V5: 물가자료26년4월호908Page | W5: TRUE | X5: 초저녹스 고효율 콘덴싱 보일러
B6: =D6&"_"&F6&"_"&G6&"_"&I6 -> M_BLR0101_VM_DY_BLR_DMXR-250PG_2500 | C6: 노통연관식 증기 보일러 (가스) | D6: {=INDEX(기계코드!$D$4:$D$1022,MATCH(1,(C6=기계코드!$F$4:$F$1022)*1,0))} -> M_BLR0101 | E6: (주)대열보일러 | F6: {=INDEX(공급업체코드!$B$3:$B$1000,MATCH(1,(E6=공급업체코드!$D$3:$D$1000)*1,0))} -> VM_DY_BLR | G6: ="DMXR-"&LEFT(I6,3)&"PG" -> DMXR-250PG | I6: 2500 | J6: =3*2+11 -> 17 | K6: S_SYS04 | L6: 380 | M6: 0.99 | N6: 0.9 | O6: 90 | P6: 8600 | Q6: 식 | T6: 159100000 | V6: 물가자료26년4월호908Page | W6: TRUE | X6: 초저녹스 고효율 콘덴싱 보일러
B7: =D7&"_"&F7&"_"&G7&"_"&I7 -> M_BLR0101_VM_DY_BLR_DMXR-300PG_3000 | C7: 노통연관식 증기 보일러 (가스) | D7: {=INDEX(기계코드!$D$4:$D$1022,MATCH(1,(C7=기계코드!$F$4:$F$1022)*1,0))} -> M_BLR0101 | E7: (주)대열보일러 | F7: {=INDEX(공급업체코드!$B$3:$B$1000,MATCH(1,(E7=공급업체코드!$D$3:$D$1000)*1,0))} -> VM_DY_BLR | G7: ="DMXR-"&LEFT(I7,3)&"PG" -> DMXR-300PG | I7: 3000 | J7: =4*2+15 -> 23 | K7: S_SYS04 | L7: 380 | M7: 0.99 | N7: 0.9 | O7: 90 | P7: 9200 | Q7: 식 | T7: 168900000 | V7: 물가자료26년4월호908Page | W7: TRUE | X7: 초저녹스 고효율 콘덴싱 보일러
B8: =D8&"_"&F8&"_"&G8&"_"&I8 -> M_BLR0101_VM_DY_BLR_DMXR-350PG_3500 | C8: 노통연관식 증기 보일러 (가스) | D8: {=INDEX(기계코드!$D$4:$D$1022,MATCH(1,(C8=기계코드!$F$4:$F$1022)*1,0))} -> M_BLR0101 | E8: (주)대열보일러 | F8: {=INDEX(공급업체코드!$B$3:$B$1000,MATCH(1,(E8=공급업체코드!$D$3:$D$1000)*1,0))} -> VM_DY_BLR | G8: ="DMXR-"&LEFT(I8,3)&"PG" -> DMXR-350PG | I8: 3500 | J8: =4*2+15 -> 23 | K8: S_SYS04 | L8: 380 | M8: 0.99 | N8: 0.9 | O8: 90 | P8: 10300 | Q8: 식 | T8: 177700000 | V8: 물가자료26년4월호908Page | W8: TRUE | X8: 초저녹스 고효율 콘덴싱 보일러
B9: =D9&"_"&F9&"_"&G9&"_"&I9 -> M_BLR0101_VM_DY_BLR_DMXR-400PG_4000 | C9: 노통연관식 증기 보일러 (가스) | D9: {=INDEX(기계코드!$D$4:$D$1022,MATCH(1,(C9=기계코드!$F$4:$F$1022)*1,0))} -> M_BLR0101 | E9: (주)대열보일러 | F9: {=INDEX(공급업체코드!$B$3:$B$1000,MATCH(1,(E9=공급업체코드!$D$3:$D$1000)*1,0))} -> VM_DY_BLR | G9: ="DMXR-"&LEFT(I9,3)&"PG" -> DMXR-400PG | I9: 4000 | J9: =4*2+18.5 -> 26.5 | K9: S_SYS04 | L9: 380 | M9: 0.99 | N9: 0.9 | O9: 90 | P9: 12200 | Q9: 식 | T9: 187700000 | V9: 물가자료26년4월호908Page | W9: TRUE | X9: 초저녹스 고효율 콘덴싱 보일러
B10: =D10&"_"&F10&"_"&G10&"_"&I10 -> M_BLR0101_VM_DY_BLR_DMXR-450PG_4500 | C10: 노통연관식 증기 보일러 (가스) | D10: {=INDEX(기계코드!$D$4:$D$1022,MATCH(1,(C10=기계코드!$F$4:$F$1022)*1,0))} -> M_BLR0101 | E10: (주)대열보일러 | F10: {=INDEX(공급업체코드!$B$3:$B$1000,MATCH(1,(E10=공급업체코드!$D$3:$D$1000)*1,0))} -> VM_DY_BLR | G10: ="DMXR-"&LEFT(I10,3)&"PG" -> DMXR-450PG | I10: 4500 | J10: =4*2+22 -> 30 | K10: S_SYS04 | L10: 380 | M10: 0.99 | N10: 0.9 | O10: 90 | P10: 12600 | Q10: 식 | T10: 204500000 | V10: 물가자료26년4월호908Page | W10: TRUE | X10: 초저녹스 고효율 콘덴싱 보일러
B11: =D11&"_"&F11&"_"&G11&"_"&I11 -> M_BLR0101_VM_DY_BLR_DMXR-500PG_5000 | C11: 노통연관식 증기 보일러 (가스) | D11: {=INDEX(기계코드!$D$4:$D$1022,MATCH(1,(C11=기계코드!$F$4:$F$1022)*1,0))} -> M_BLR0101 | E11: (주)대열보일러 | F11: {=INDEX(공급업체코드!$B$3:$B$1000,MATCH(1,(E11=공급업체코드!$D$3:$D$1000)*1,0))} -> VM_DY_BLR | G11: ="DMXR-"&LEFT(I11,3)&"PG" -> DMXR-500PG | I11: 5000 | J11: =4*2+22 -> 30 | K11: S_SYS04 | L11: 380 | M11: 0.99 | N11: 0.9 | O11: 90 | P11: 19100 | Q11: 식 | T11: 219100000 | V11: 물가자료26년4월호908Page | W11: TRUE | X11: 초저녹스 고효율 콘덴싱 보일러
B12: =D12&"_"&F12&"_"&G12&"_"&I12 -> M_BLR0101_VM_DY_BLR_DMXR-600PG_6000 | C12: 노통연관식 증기 보일러 (가스) | D12: {=INDEX(기계코드!$D$4:$D$1022,MATCH(1,(C12=기계코드!$F$4:$F$1022)*1,0))} -> M_BLR0101 | E12: (주)대열보일러 | F12: {=INDEX(공급업체코드!$B$3:$B$1000,MATCH(1,(E12=공급업체코드!$D$3:$D$1000)*1,0))} -> VM_DY_BLR | G12: ="DMXR-"&LEFT(I12,3)&"PG" -> DMXR-600PG | I12: 6000 | J12: =5.5*2+30 -> 41 | K12: S_SYS04 | L12: 380 | M12: 0.99 | N12: 0.9 | O12: 90 | P12: 23600 | Q12: 식 | T12: 238500000 | V12: 물가자료26년4월호908Page | W12: TRUE | X12: 초저녹스 고효율 콘덴싱 보일러
B13: =D13&"_"&F13&"_"&G13&"_"&I13 -> M_BLR0101_VM_DY_BLR_DMXR-700PG_7000 | C13: 노통연관식 증기 보일러 (가스) | D13: {=INDEX(기계코드!$D$4:$D$1022,MATCH(1,(C13=기계코드!$F$4:$F$1022)*1,0))} -> M_BLR0101 | E13: (주)대열보일러 | F13: {=INDEX(공급업체코드!$B$3:$B$1000,MATCH(1,(E13=공급업체코드!$D$3:$D$1000)*1,0))} -> VM_DY_BLR | G13: ="DMXR-"&LEFT(I13,3)&"PG" -> DMXR-700PG | I13: 7000 | J13: =5.5*2+30 -> 41 | K13: S_SYS04 | L13: 380 | M13: 0.99 | N13: 0.9 | O13: 90 | P13: 27600 | Q13: 식 | T13: 266100000 | V13: 물가자료26년4월호908Page | W13: TRUE | X13: 초저녹스 고효율 콘덴싱 보일러
B14: =D14&"_"&F14&"_"&G14&"_"&I14 -> M_BLR0101_VM_DY_BLR_DMXR-800PG_8000 | C14: 노통연관식 증기 보일러 (가스) | D14: {=INDEX(기계코드!$D$4:$D$1022,MATCH(1,(C14=기계코드!$F$4:$F$1022)*1,0))} -> M_BLR0101 | E14: (주)대열보일러 | F14: {=INDEX(공급업체코드!$B$3:$B$1000,MATCH(1,(E14=공급업체코드!$D$3:$D$1000)*1,0))} -> VM_DY_BLR | G14: ="DMXR-"&LEFT(I14,3)&"PG" -> DMXR-800PG | I14: 8000 | J14: =7.5*2+37 -> 52 | K14: S_SYS04 | L14: 380 | M14: 0.99 | N14: 0.9 | O14: 90 | P14: 28200 | Q14: 식 | T14: 272800000 | V14: 물가자료26년4월호908Page | W14: TRUE | X14: 초저녹스 고효율 콘덴싱 보일러
B15: =D15&"_"&F15&"_"&G15&"_"&I15 -> M_BLR0101_VM_DY_BLR_DMXR-1000PG_10000 | C15: 노통연관식 증기 보일러 (가스) | D15: {=INDEX(기계코드!$D$4:$D$1022,MATCH(1,(C15=기계코드!$F$4:$F$1022)*1,0))} -> M_BLR0101 | E15: (주)대열보일러 | F15: {=INDEX(공급업체코드!$B$3:$B$1000,MATCH(1,(E15=공급업체코드!$D$3:$D$1000)*1,0))} -> VM_DY_BLR | G15: ="DMXR-"&LEFT(I15,4)&"PG" -> DMXR-1000PG | I15: 10000 | J15: =7.5*2+45 -> 60 | K15: S_SYS04 | L15: 380 | M15: 0.99 | N15: 0.9 | O15: 90 | P15: 28300 | Q15: 식 | T15: 333500000 | V15: 물가자료26년4월호908Page | W15: TRUE | X15: 초저녹스 고효율 콘덴싱 보일러
B16: =D16&"_"&F16&"_"&G16&"_"&I16 -> M_BLR0101_VM_DY_BLR_DMXR-1200PG_12000 | C16: 노통연관식 증기 보일러 (가스) | D16: {=INDEX(기계코드!$D$4:$D$1022,MATCH(1,(C16=기계코드!$F$4:$F$1022)*1,0))} -> M_BLR0101 | E16: (주)대열보일러 | F16: {=INDEX(공급업체코드!$B$3:$B$1000,MATCH(1,(E16=공급업체코드!$D$3:$D$1000)*1,0))} -> VM_DY_BLR | G16: ="DMXR-"&LEFT(I16,4)&"PG" -> DMXR-1200PG | I16: 12000 | J16: =11*2+55 -> 77 | K16: S_SYS04 | L16: 380 | M16: 0.99 | N16: 0.9 | O16: 90 | P16: 35200 | Q16: 식 | T16: 403600000 | V16: 물가자료26년4월호908Page | W16: TRUE | X16: 초저녹스 고효율 콘덴싱 보일러
B17: =D17&"_"&F17&"_"&G17&"_"&I17 -> M_BLR0101_VM_DY_BLR_DMXR-1500PG_15000 | C17: 노통연관식 증기 보일러 (가스) | D17: {=INDEX(기계코드!$D$4:$D$1022,MATCH(1,(C17=기계코드!$F$4:$F$1022)*1,0))} -> M_BLR0101 | E17: (주)대열보일러 | F17: {=INDEX(공급업체코드!$B$3:$B$1000,MATCH(1,(E17=공급업체코드!$D$3:$D$1000)*1,0))} -> VM_DY_BLR | G17: ="DMXR-"&LEFT(I17,4)&"PG" -> DMXR-1500PG | I17: 15000 | J17: =15*2+75 -> 105 | K17: S_SYS04 | L17: 380 | M17: 0.99 | N17: 0.9 | O17: 90 | P17: 36800 | Q17: 식 | T17: 426600000 | V17: 물가자료26년4월호908Page | W17: TRUE | X17: 초저녹스 고효율 콘덴싱 보일러
B18: =D18&"_"&F18&"_"&G18&"_"&I18 -> M_BLR0101_VM_DY_BLR_DMXR-2000PG_20000 | C18: 노통연관식 증기 보일러 (가스) | D18: {=INDEX(기계코드!$D$4:$D$1022,MATCH(1,(C18=기계코드!$F$4:$F$1022)*1,0))} -> M_BLR0101 | E18: (주)대열보일러 | F18: {=INDEX(공급업체코드!$B$3:$B$1000,MATCH(1,(E18=공급업체코드!$D$3:$D$1000)*1,0))} -> VM_DY_BLR | G18: ="DMXR-"&LEFT(I18,4)&"PG" -> DMXR-2000PG | I18: 20000 | J18: =15*2+90 -> 120 | K18: S_SYS04 | L18: 380 | M18: 0.99 | N18: 0.9 | O18: 90 | P18: 44600 | Q18: 식 | T18: 526600000 | V18: 물가자료26년4월호908Page | W18: TRUE | X18: 초저녹스 고효율 콘덴싱 보일러
B19: =D19&"_"&F19&"_"&G19&"_"&H19 -> M_BLR0201_VM_DY_BLR_DMXR-1PG_1000000 | C19: 노통연관식 온수 보일러 (가스) | D19: {=INDEX(기계코드!$D$4:$D$1022,MATCH(1,(C19=기계코드!$F$4:$F$1022)*1,0))} -> M_BLR0201 | E19: (주)대열보일러 | F19: {=INDEX(공급업체코드!$B$3:$B$1000,MATCH(1,(E19=공급업체코드!$D$3:$D$1000)*1,0))} -> VM_DY_BLR | G19: ="DMXR-"&LEFT(H19,1)&"PG" -> DMXR-1PG | H19: 1000000 | J19: =2.2*2+5.5 -> 9.9 | K19: S_SYS04 | L19: 380 | M19: 0.99 | N19: 0.9 | O19: 90 | P19: 7600 | Q19: 식 | T19: 117700000 | V19: 물가자료26년4월호908Page | W19: TRUE | X19: 초저녹스 고효율 콘덴싱 중온수 보일러
B20: =D20&"_"&F20&"_"&G20&"_"&H20 -> M_BLR0201_VM_DY_BLR_DMXR-1.5PG_1500000 | C20: 노통연관식 온수 보일러 (가스) | D20: {=INDEX(기계코드!$D$4:$D$1022,MATCH(1,(C20=기계코드!$F$4:$F$1022)*1,0))} -> M_BLR0201 | E20: (주)대열보일러 | F20: {=INDEX(공급업체코드!$B$3:$B$1000,MATCH(1,(E20=공급업체코드!$D$3:$D$1000)*1,0))} -> VM_DY_BLR | G20: DMXR-1.5PG | H20: 1500000 | J20: =3*2+11 -> 17 | K20: S_SYS04 | L20: 380 | M20: 0.99 | N20: 0.9 | O20: 90 | P20: 8600 | Q20: 식 | T20: 138700000 | V20: 물가자료26년4월호908Page | W20: TRUE | X20: 초저녹스 고효율 콘덴싱 중온수 보일러
B21: =D21&"_"&F21&"_"&G21&"_"&H21 -> M_BLR0201_VM_DY_BLR_DMXR-2PG_2000000 | C21: 노통연관식 온수 보일러 (가스) | D21: {=INDEX(기계코드!$D$4:$D$1022,MATCH(1,(C21=기계코드!$F$4:$F$1022)*1,0))} -> M_BLR0201 | E21: (주)대열보일러 | F21: {=INDEX(공급업체코드!$B$3:$B$1000,MATCH(1,(E21=공급업체코드!$D$3:$D$1000)*1,0))} -> VM_DY_BLR | G21: ="DMXR-"&LEFT(H21,1)&"PG" -> DMXR-2PG | H21: 2000000 | J21: =4*2+15 -> 23 | K21: S_SYS04 | L21: 380 | M21: 0.99 | N21: 0.9 | O21: 90 | P21: 9200 | Q21: 식 | T21: 148400000 | V21: 물가자료26년4월호908Page | W21: TRUE | X21: 초저녹스 고효율 콘덴싱 중온수 보일러
B22: =D22&"_"&F22&"_"&G22&"_"&H22 -> M_BLR0201_VM_DY_BLR_DMXR-2.5PG_2500000 | C22: 노통연관식 온수 보일러 (가스) | D22: {=INDEX(기계코드!$D$4:$D$1022,MATCH(1,(C22=기계코드!$F$4:$F$1022)*1,0))} -> M_BLR0201 | E22: (주)대열보일러 | F22: {=INDEX(공급업체코드!$B$3:$B$1000,MATCH(1,(E22=공급업체코드!$D$3:$D$1000)*1,0))} -> VM_DY_BLR | G22: DMXR-2.5PG | H22: 2500000 | J22: =4*2+18.5 -> 26.5 | K22: S_SYS04 | L22: 380 | M22: 0.99 | N22: 0.9 | O22: 90 | P22: 12200 | Q22: 식 | T22: 166300000 | V22: 물가자료26년4월호908Page | W22: TRUE | X22: 초저녹스 고효율 콘덴싱 중온수 보일러
B23: =D23&"_"&F23&"_"&G23&"_"&H23 -> M_BLR0201_VM_DY_BLR_DMXR-3PG_3000000 | C23: 노통연관식 온수 보일러 (가스) | D23: {=INDEX(기계코드!$D$4:$D$1022,MATCH(1,(C23=기계코드!$F$4:$F$1022)*1,0))} -> M_BLR0201 | E23: (주)대열보일러 | F23: {=INDEX(공급업체코드!$B$3:$B$1000,MATCH(1,(E23=공급업체코드!$D$3:$D$1000)*1,0))} -> VM_DY_BLR | G23: ="DMXR-"&LEFT(H23,1)&"PG" -> DMXR-3PG | H23: 3000000 | J23: =4*2+22 -> 30 | K23: S_SYS04 | L23: 380 | M23: 0.99 | N23: 0.9 | O23: 90 | P23: 12600 | Q23: 식 | T23: 179600000 | V23: 물가자료26년4월호908Page | W23: TRUE | X23: 초저녹스 고효율 콘덴싱 중온수 보일러
B24: =D24&"_"&F24&"_"&G24&"_"&H24 -> M_BLR0201_VM_DY_BLR_DMXR-3.5PG_3500000 | C24: 노통연관식 온수 보일러 (가스) | D24: {=INDEX(기계코드!$D$4:$D$1022,MATCH(1,(C24=기계코드!$F$4:$F$1022)*1,0))} -> M_BLR0201 | E24: (주)대열보일러 | F24: {=INDEX(공급업체코드!$B$3:$B$1000,MATCH(1,(E24=공급업체코드!$D$3:$D$1000)*1,0))} -> VM_DY_BLR | G24: DMXR-3.5PG | H24: 3500000 | J24: =4*2+22 -> 30 | K24: S_SYS04 | L24: 380 | M24: 0.99 | N24: 0.9 | O24: 90 | P24: 19100 | Q24: 식 | T24: 195700000 | V24: 물가자료26년4월호908Page | W24: TRUE | X24: 초저녹스 고효율 콘덴싱 중온수 보일러
B25: =D25&"_"&F25&"_"&G25&"_"&H25 -> M_BLR0201_VM_DY_BLR_DMXR-4PG_4000000 | C25: 노통연관식 온수 보일러 (가스) | D25: {=INDEX(기계코드!$D$4:$D$1022,MATCH(1,(C25=기계코드!$F$4:$F$1022)*1,0))} -> M_BLR0201 | E25: (주)대열보일러 | F25: {=INDEX(공급업체코드!$B$3:$B$1000,MATCH(1,(E25=공급업체코드!$D$3:$D$1000)*1,0))} -> VM_DY_BLR | G25: ="DMXR-"&LEFT(H25,1)&"PG" -> DMXR-4PG | H25: 4000000 | J25: =5.5*2+30 -> 41 | K25: S_SYS04 | L25: 380 | M25: 0.99 | N25: 0.9 | O25: 90 | P25: 23600 | Q25: 식 | T25: 214500000 | V25: 물가자료26년4월호908Page | W25: TRUE | X25: 초저녹스 고효율 콘덴싱 중온수 보일러
B26: =D26&"_"&F26&"_"&G26&"_"&H26 -> M_BLR0201_VM_DY_BLR_DMXR-4.5PG_4500000 | C26: 노통연관식 온수 보일러 (가스) | D26: {=INDEX(기계코드!$D$4:$D$1022,MATCH(1,(C26=기계코드!$F$4:$F$1022)*1,0))} -> M_BLR0201 | E26: (주)대열보일러 | F26: {=INDEX(공급업체코드!$B$3:$B$1000,MATCH(1,(E26=공급업체코드!$D$3:$D$1000)*1,0))} -> VM_DY_BLR | G26: DMXR-4.5PG | H26: 4500000 | J26: =5.5*2+30 -> 41 | K26: S_SYS04 | L26: 380 | M26: 0.99 | N26: 0.9 | O26: 90 | P26: 27600 | Q26: 식 | T26: 240000000 | V26: 물가자료26년4월호908Page | W26: TRUE | X26: 초저녹스 고효율 콘덴싱 중온수 보일러
B27: =D27&"_"&F27&"_"&G27&"_"&H27 -> M_BLR0201_VM_DY_BLR_DMXR-5PG_5000000 | C27: 노통연관식 온수 보일러 (가스) | D27: {=INDEX(기계코드!$D$4:$D$1022,MATCH(1,(C27=기계코드!$F$4:$F$1022)*1,0))} -> M_BLR0201 | E27: (주)대열보일러 | F27: {=INDEX(공급업체코드!$B$3:$B$1000,MATCH(1,(E27=공급업체코드!$D$3:$D$1000)*1,0))} -> VM_DY_BLR | G27: ="DMXR-"&LEFT(H27,1)&"PG" -> DMXR-5PG | H27: 5000000 | J27: =7.5*2+37 -> 52 | K27: S_SYS04 | L27: 380 | M27: 0.99 | N27: 0.9 | O27: 90 | P27: 28200 | Q27: 식 | T27: 247100000 | V27: 물가자료26년4월호908Page | W27: TRUE | X27: 초저녹스 고효율 콘덴싱 중온수 보일러
B28: =D28&"_"&F28&"_"&G28&"_"&H28 -> M_BLR0201_VM_DY_BLR_DMXR-5.5PG_5500000 | C28: 노통연관식 온수 보일러 (가스) | D28: {=INDEX(기계코드!$D$4:$D$1022,MATCH(1,(C28=기계코드!$F$4:$F$1022)*1,0))} -> M_BLR0201 | E28: (주)대열보일러 | F28: {=INDEX(공급업체코드!$B$3:$B$1000,MATCH(1,(E28=공급업체코드!$D$3:$D$1000)*1,0))} -> VM_DY_BLR | G28: DMXR-5.5PG | H28: 5500000 | J28: =7.5*2+37 -> 52 | K28: S_SYS04 | L28: 380 | M28: 0.99 | N28: 0.9 | O28: 90 | P28: 28200 | Q28: 식 | T28: 247100000 | V28: 물가자료26년4월호908Page | W28: TRUE | X28: 초저녹스 고효율 콘덴싱 중온수 보일러
B29: =D29&"_"&F29&"_"&G29&"_"&H29 -> M_BLR0201_VM_DY_BLR_DMXR-6PG_6000000 | C29: 노통연관식 온수 보일러 (가스) | D29: {=INDEX(기계코드!$D$4:$D$1022,MATCH(1,(C29=기계코드!$F$4:$F$1022)*1,0))} -> M_BLR0201 | E29: (주)대열보일러 | F29: {=INDEX(공급업체코드!$B$3:$B$1000,MATCH(1,(E29=공급업체코드!$D$3:$D$1000)*1,0))} -> VM_DY_BLR | G29: ="DMXR-"&LEFT(H29,1)&"PG" -> DMXR-6PG | H29: 6000000 | J29: =7.5*2+45 -> 60 | K29: S_SYS04 | L29: 380 | M29: 0.99 | N29: 0.9 | O29: 90 | P29: 28300 | Q29: 식 | T29: 304000000 | V29: 물가자료26년4월호908Page | W29: TRUE | X29: 초저녹스 고효율 콘덴싱 중온수 보일러
B30: =D30&"_"&F30&"_"&G30&"_"&H30 -> M_BLR0201_VM_DY_BLR_DMXR-6.5PG_6500000 | C30: 노통연관식 온수 보일러 (가스) | D30: {=INDEX(기계코드!$D$4:$D$1022,MATCH(1,(C30=기계코드!$F$4:$F$1022)*1,0))} -> M_BLR0201 | E30: (주)대열보일러 | F30: {=INDEX(공급업체코드!$B$3:$B$1000,MATCH(1,(E30=공급업체코드!$D$3:$D$1000)*1,0))} -> VM_DY_BLR | G30: DMXR-6.5PG | H30: 6500000 | J30: =7.5*2+45 -> 60 | K30: S_SYS04 | L30: 380 | M30: 0.99 | N30: 0.9 | O30: 90 | P30: 28300 | Q30: 식 | T30: 304000000 | V30: 물가자료26년4월호908Page | W30: TRUE | X30: 초저녹스 고효율 콘덴싱 중온수 보일러
B31: =D31&"_"&F31&"_"&G31&"_"&H31 -> M_BLR0201_VM_DY_BLR_DMXR-7PG_7000000 | C31: 노통연관식 온수 보일러 (가스) | D31: {=INDEX(기계코드!$D$4:$D$1022,MATCH(1,(C31=기계코드!$F$4:$F$1022)*1,0))} -> M_BLR0201 | E31: (주)대열보일러 | F31: {=INDEX(공급업체코드!$B$3:$B$1000,MATCH(1,(E31=공급업체코드!$D$3:$D$1000)*1,0))} -> VM_DY_BLR | G31: ="DMXR-"&LEFT(H31,1)&"PG" -> DMXR-7PG | H31: 7000000 | J31: =11*2+55 -> 77 | K31: S_SYS04 | L31: 380 | M31: 0.99 | N31: 0.9 | O31: 90 | P31: 35200 | Q31: 식 | T31: 364200000 | V31: 물가자료26년4월호908Page | W31: TRUE | X31: 초저녹스 고효율 콘덴싱 중온수 보일러
B32: =D32&"_"&F32&"_"&G32&"_"&H32 -> M_BLR0201_VM_DY_BLR_DMXR-8PG_8000000 | C32: 노통연관식 온수 보일러 (가스) | D32: {=INDEX(기계코드!$D$4:$D$1022,MATCH(1,(C32=기계코드!$F$4:$F$1022)*1,0))} -> M_BLR0201 | E32: (주)대열보일러 | F32: {=INDEX(공급업체코드!$B$3:$B$1000,MATCH(1,(E32=공급업체코드!$D$3:$D$1000)*1,0))} -> VM_DY_BLR | G32: ="DMXR-"&LEFT(H32,1)&"PG" -> DMXR-8PG | H32: 8000000 | J32: =11*2+55 -> 77 | K32: S_SYS04 | L32: 380 | M32: 0.99 | N32: 0.9 | O32: 90 | P32: 35200 | Q32: 식 | T32: 364200000 | V32: 물가자료26년4월호908Page | W32: TRUE | X32: 초저녹스 고효율 콘덴싱 중온수 보일러
B33: =D33&"_"&F33&"_"&G33&"_"&H33 -> M_BLR0201_VM_DY_BLR_DMXR-10PG_10000000 | C33: 노통연관식 온수 보일러 (가스) | D33: {=INDEX(기계코드!$D$4:$D$1022,MATCH(1,(C33=기계코드!$F$4:$F$1022)*1,0))} -> M_BLR0201 | E33: (주)대열보일러 | F33: {=INDEX(공급업체코드!$B$3:$B$1000,MATCH(1,(E33=공급업체코드!$D$3:$D$1000)*1,0))} -> VM_DY_BLR | G33: ="DMXR-"&LEFT(H33,2)&"PG" -> DMXR-10PG | H33: 10000000 | J33: =15*2+75 -> 105 | K33: S_SYS04 | L33: 380 | M33: 0.99 | N33: 0.9 | O33: 90 | P33: 36800 | Q33: 식 | T33: 390300000 | V33: 물가자료26년4월호908Page | W33: TRUE | X33: 초저녹스 고효율 콘덴싱 중온수 보일러
B34: =D34&"_"&F34&"_"&G34&"_"&H34 -> M_BLR0201_VM_DY_BLR_DMXR-13PG_13000000 | C34: 노통연관식 온수 보일러 (가스) | D34: {=INDEX(기계코드!$D$4:$D$1022,MATCH(1,(C34=기계코드!$F$4:$F$1022)*1,0))} -> M_BLR0201 | E34: (주)대열보일러 | F34: {=INDEX(공급업체코드!$B$3:$B$1000,MATCH(1,(E34=공급업체코드!$D$3:$D$1000)*1,0))} -> VM_DY_BLR | G34: ="DMXR-"&LEFT(H34,2)&"PG" -> DMXR-13PG | H34: 13000000 | J34: =15*2+90 -> 120 | K34: S_SYS04 | L34: 380 | M34: 0.99 | N34: 0.9 | O34: 90 | P34: 44600 | Q34: 식 | T34: 493500000 | V34: 물가자료26년4월호908Page | W34: TRUE | X34: 초저녹스 고효율 콘덴싱 중온수 보일러

Sheet 바이오가스 설비
B1: 장비코드 | D1: 장비유형 | F1: 공급업체명 | G1: 모델명 | H1: 용량(N㎥/hr) | I1: 동력(kW) | J1: 기동방식 | K1: 정격전압(V) | L1: 효율(%) | M1: 역률(%) | N1: 수용율(%) | O1: 총중량(kg) | P1: 단위 | Q1: 호표(1) | R1: 분류 | S1: 단가(원) | T1: 견적가(원) | U1: 단가출처 | V1: 사용여부 | W1: 장비설명 | X1: 단위시스템코드
B2: equipment_code | C2: 작업용 필드 | D2: equipment_type | E2: 작업용 필드 | F2: vendor_id | G2: model_number | H2: i_capacity_Nm3_h | I2: s_power_kW | J2: s_ctrl_method | K2: s_rated_volt_V | L2: s_efficiency_percent | M2: s_pwr_factor_percent | N2: s_demand_factor_percent | O2: s_total_wgt_kg | P2: s_unit_NONE | Q2: s_primary_item_no_NONE | R2: s_remark_NONE | S2: o_unit_price_KRW | T2: o_invoice_price_KRW | U2: o_price_reference | V2: is_active | W2: description | X2: unit_system_code
B3: =D3&"_"&F3&"_"&H3 -> M_BGF0101_VM_0000_500 | C3: 이중막 가스 저장조 | D3: {=INDEX(기계코드!$D$4:$D$1022,MATCH(1,(C3=기계코드!$F$4:$F$1022)*1,0))} -> M_BGF0101 | E3: 미지정업체 | F3: {=INDEX(공급업체코드!$B$3:$B$1000,MATCH(1,(E3=공급업체코드!$D$3:$D$1000)*1,0))} -> VM_0000 | H3: 500 | P3: 대 | S3: 0 | U3: 견적 필요 | V3: TRUE
B4: =D4&"_"&F4&"_"&H4 -> M_BGF0101_VM_0000_1000 | C4: 이중막 가스 저장조 | D4: {=INDEX(기계코드!$D$4:$D$1022,MATCH(1,(C4=기계코드!$F$4:$F$1022)*1,0))} -> M_BGF0101 | E4: 미지정업체 | F4: {=INDEX(공급업체코드!$B$3:$B$1000,MATCH(1,(E4=공급업체코드!$D$3:$D$1000)*1,0))} -> VM_0000 | H4: 1000 | P4: 대 | S4: 0 | U4: 견적 필요 | V4: TRUE
B5: =D5&"_"&F5&"_"&H5 -> M_BGF0101_VM_0000_1500 | C5: 이중막 가스 저장조 | D5: {=INDEX(기계코드!$D$4:$D$1022,MATCH(1,(C5=기계코드!$F$4:$F$1022)*1,0))} -> M_BGF0101 | E5: 미지정업체 | F5: {=INDEX(공급업체코드!$B$3:$B$1000,MATCH(1,(E5=공급업체코드!$D$3:$D$1000)*1,0))} -> VM_0000 | H5: 1500 | P5: 대 | S5: 0 | U5: 견적 필요 | V5: TRUE
B6: =D6&"_"&F6&"_"&H6 -> M_BGF0101_VM_0000_2000 | C6: 이중막 가스 저장조 | D6: {=INDEX(기계코드!$D$4:$D$1022,MATCH(1,(C6=기계코드!$F$4:$F$1022)*1,0))} -> M_BGF0101 | E6: 미지정업체 | F6: {=INDEX(공급업체코드!$B$3:$B$1000,MATCH(1,(E6=공급업체코드!$D$3:$D$1000)*1,0))} -> VM_0000 | H6: 2000 | P6: 대 | S6: 0 | U6: 견적 필요 | V6: TRUE
B7: =D7&"_"&F7&"_"&H7 -> M_BGF0101_VM_0000_2500 | C7: 이중막 가스 저장조 | D7: {=INDEX(기계코드!$D$4:$D$1022,MATCH(1,(C7=기계코드!$F$4:$F$1022)*1,0))} -> M_BGF0101 | E7: 미지정업체 | F7: {=INDEX(공급업체코드!$B$3:$B$1000,MATCH(1,(E7=공급업체코드!$D$3:$D$1000)*1,0))} -> VM_0000 | H7: 2500 | P7: 대 | S7: 0 | U7: 견적 필요 | V7: TRUE
B8: =D8&"_"&F8&"_"&H8 -> M_BGF0101_VM_0000_3000 | C8: 이중막 가스 저장조 | D8: {=INDEX(기계코드!$D$4:$D$1022,MATCH(1,(C8=기계코드!$F$4:$F$1022)*1,0))} -> M_BGF0101 | E8: 미지정업체 | F8: {=INDEX(공급업체코드!$B$3:$B$1000,MATCH(1,(E8=공급업체코드!$D$3:$D$1000)*1,0))} -> VM_0000 | H8: 3000 | P8: 대 | S8: 0 | U8: 견적 필요 | V8: TRUE
B9: =D9&"_"&F9&"_"&H9 -> M_BGF0101_VM_0000_3500 | C9: 이중막 가스 저장조 | D9: {=INDEX(기계코드!$D$4:$D$1022,MATCH(1,(C9=기계코드!$F$4:$F$1022)*1,0))} -> M_BGF0101 | E9: 미지정업체 | F9: {=INDEX(공급업체코드!$B$3:$B$1000,MATCH(1,(E9=공급업체코드!$D$3:$D$1000)*1,0))} -> VM_0000 | H9: 3500 | P9: 대 | S9: 0 | U9: 견적 필요 | V9: TRUE
B10: =D10&"_"&F10&"_"&H10 -> M_BGF0101_VM_0000_4000 | C10: 이중막 가스 저장조 | D10: {=INDEX(기계코드!$D$4:$D$1022,MATCH(1,(C10=기계코드!$F$4:$F$1022)*1,0))} -> M_BGF0101 | E10: 미지정업체 | F10: {=INDEX(공급업체코드!$B$3:$B$1000,MATCH(1,(E10=공급업체코드!$D$3:$D$1000)*1,0))} -> VM_0000 | H10: 4000 | P10: 대 | S10: 0 | U10: 견적 필요 | V10: TRUE
B11: =D11&"_"&F11&"_"&H11 -> M_BGF0101_VM_0000_4500 | C11: 이중막 가스 저장조 | D11: {=INDEX(기계코드!$D$4:$D$1022,MATCH(1,(C11=기계코드!$F$4:$F$1022)*1,0))} -> M_BGF0101 | E11: 미지정업체 | F11: {=INDEX(공급업체코드!$B$3:$B$1000,MATCH(1,(E11=공급업체코드!$D$3:$D$1000)*1,0))} -> VM_0000 | H11: 4500 | P11: 대 | S11: 0 | U11: 견적 필요 | V11: TRUE
B12: =D12&"_"&F12&"_"&H12 -> M_BGF0101_VM_0000_5000 | C12: 이중막 가스 저장조 | D12: {=INDEX(기계코드!$D$4:$D$1022,MATCH(1,(C12=기계코드!$F$4:$F$1022)*1,0))} -> M_BGF0101 | E12: 미지정업체 | F12: {=INDEX(공급업체코드!$B$3:$B$1000,MATCH(1,(E12=공급업체코드!$D$3:$D$1000)*1,0))} -> VM_0000 | H12: 5000 | P12: 대 | S12: 0 | U12: 견적 필요 | V12: TRUE
B14: =D14&"_"&F14&"_"&H14 -> M_BGF0201_VM_0000_250 | C14: 건식 탈황설비 | D14: {=INDEX(기계코드!$D$4:$D$1022,MATCH(1,(C14=기계코드!$F$4:$F$1022)*1,0))} -> M_BGF0201 | E14: 미지정업체 | F14: {=INDEX(공급업체코드!$B$3:$B$1000,MATCH(1,(E14=공급업체코드!$D$3:$D$1000)*1,0))} -> VM_0000 | H14: 250 | P14: 식 | S14: 0 | U14: 견적 필요 | V14: TRUE
B15: =D15&"_"&F15&"_"&H15 -> M_BGF0201_VM_0000_500 | C15: 건식 탈황설비 | D15: {=INDEX(기계코드!$D$4:$D$1022,MATCH(1,(C15=기계코드!$F$4:$F$1022)*1,0))} -> M_BGF0201 | E15: 미지정업체 | F15: {=INDEX(공급업체코드!$B$3:$B$1000,MATCH(1,(E15=공급업체코드!$D$3:$D$1000)*1,0))} -> VM_0000 | H15: 500 | P15: 식 | S15: 0 | U15: 견적 필요 | V15: TRUE
... B45: =D45&"_"&F45&"_"&H45 -> M_BGF0401_VM_0000_2500 | C45: 노내연소식 잉여가스 연소기 | D45: {=INDEX(기계코드!$D$4:$D$1022,MATCH(1,(C45=기계코드!$F$4:$F$1022)*1,0))} -> M_BGF0401 | E45: 미지정업체 | F45: {=INDEX(공급업체코드!$B$3:$B$1000,MATCH(1,(E45=공급업체코드!$D$3:$D$1000)*1,0))} -> VM_0000 | H45: 2500 | P45: 대 | S45: 0 | U45: 견적 필요 | V45: TRUE

Sheet 발전설비
B1: 장비코드 | D1: 장비유형 | F1: 공급업체명 | G1: 모델명 | H1: 최대 동력(kW) | I1: 동력(kW) | J1: 기동방식 | K1: 정격전압(V) | L1: 효율(%) | M1: 역률(%) | N1: 수용율(%) | O1: 총중량(kg) | P1: 단위 | Q1: 호표(1) | R1: 분류 | S1: 단가(원) | T1: 견적가(원) | U1: 단가출처 | V1: 사용여부 | W1: 장비설명 | X1: 단위시스템코드
B2: equipment_code | C2: 작업용 필드 | D2: equipment_type | E2: 작업용 필드 | F2: vendor_id | G2: model_number | H2: i_max_power_kW | I2: s_power_kW | J2: s_ctrl_method | K2: s_rated_volt_V | L2: s_efficiency_percent | M2: s_pwr_factor_percent | N2: s_demand_factor_percent | O2: s_total_wgt_kg | P2: s_unit_NONE | Q2: s_primary_item_no_NONE | R2: s_remark_NONE | S2: o_unit_price_KRW | T2: o_invoice_price_KRW | U2: o_price_reference | V2: is_active | W2: description | X2: unit_system_code
B3: =D3&"_"&F3&"_"&H3 -> M_PGE0101_VM_0000_130 | C3: 가스 엔진 발전기 | D3: {=INDEX(기계코드!$D$4:$D$1022,MATCH(1,(C3=기계코드!$F$4:$F$1022)*1,0))} -> M_PGE0101 | E3: 미지정업체 | F3: {=INDEX(공급업체코드!$B$3:$B$1000,MATCH(1,(E3=공급업체코드!$D$3:$D$1000)*1,0))} -> VM_0000 | H3: 130 | P3: 식 | S3: 0 | U3: 견적 필요 | V3: TRUE
B4: =D4&"_"&F4&"_"&H4 -> M_PGE0101_VM_0000_240 | C4: 가스 엔진 발전기 | D4: {=INDEX(기계코드!$D$4:$D$1022,MATCH(1,(C4=기계코드!$F$4:$F$1022)*1,0))} -> M_PGE0101 | E4: 미지정업체 | F4: {=INDEX(공급업체코드!$B$3:$B$1000,MATCH(1,(E4=공급업체코드!$D$3:$D$1000)*1,0))} -> VM_0000 | H4: 240 | P4: 식 | S4: 0 | U4: 견적 필요 | V4: TRUE
B5: =D5&"_"&F5&"_"&H5 -> M_PGE0101_VM_0000_360 | C5: 가스 엔진 발전기 | D5: {=INDEX(기계코드!$D$4:$D$1022,MATCH(1,(C5=기계코드!$F$4:$F$1022)*1,0))} -> M_PGE0101 | E5: 미지정업체 | F5: {=INDEX(공급업체코드!$B$3:$B$1000,MATCH(1,(E5=공급업체코드!$D$3:$D$1000)*1,0))} -> VM_0000 | H5: 360 | P5: 식 | S5: 0 | U5: 견적 필요 | V5: TRUE
B6: =D6&"_"&F6&"_"&H6 -> M_PGE0101_VM_0000_600 | C6: 가스 엔진 발전기 | D6: {=INDEX(기계코드!$D$4:$D$1022,MATCH(1,(C6=기계코드!$F$4:$F$1022)*1,0))} -> M_PGE0101 | E6: 미지정업체 | F6: {=INDEX(공급업체코드!$B$3:$B$1000,MATCH(1,(E6=공급업체코드!$D$3:$D$1000)*1,0))} -> VM_0000 | H6: 600 | P6: 식 | S6: 0 | U6: 견적 필요 | V6: TRUE

Sheet 생물반응기
B1: 장비코드 | D1: 장비유형 | F1: 공급업체명 | G1: 모델명 | H1: 용량(㎥) | I1: 외경(mm) | J1: 전고(m) | K1: 단위 | L1: 호표(1) | M1: 분류 | N1: 단가(원) | O1: 견적가(원) | P1: 단가출처 | Q1: 사용여부 | R1: 장비설명 | S1: 단위시스템코드
B2: equipment_code | C2: 작업용 필드 | D2: equipment_type | E2: 작업용 필드 | F2: vendor_id | G2: model_number | H2: i_capacity_m3 | I2: s_dia_mm | J2: s_height_m | K2: s_unit_NONE | L2: s_primary_item_no_NONE | M2: s_remark_NONE | N2: o_unit_price_KRW | O2: o_invoice_price_KRW | P2: o_price_reference | Q2: is_active | R2: description | S2: unit_system_code
B3: =D3&"_"&F3&"_"&H3 -> M_BRX01_VM_BKT_2 | C3: Air-lift Type 그래뉼 생성장치 | D3: {=INDEX(기계코드!$D$4:$D$1022,MATCH(1,(C3=기계코드!$F$4:$F$1022)*1,0))} -> M_BRX01 | E3: (주)부강테크 | F3: {=INDEX(공급업체코드!$B$3:$B$1000,MATCH(1,(E3=공급업체코드!$D$3:$D$1000)*1,0))} -> VM_BKT | G3: AGR2 | H3: 2 | K3: 식 | M3: 공법 | N3: 999 | P3: 견적가 | Q3: TRUE
B4: =D4&"_"&F4&"_"&H4 -> M_BRX01_VM_BKT_10 | C4: Air-lift Type 그래뉼 생성장치 | D4: {=INDEX(기계코드!$D$4:$D$1022,MATCH(1,(C4=기계코드!$F$4:$F$1022)*1,0))} -> M_BRX01 | E4: (주)부강테크 | F4: {=INDEX(공급업체코드!$B$3:$B$1000,MATCH(1,(E4=공급업체코드!$D$3:$D$1000)*1,0))} -> VM_BKT | G4: AGR10 | H4: 10 | K4: 식 | M4: 공법 | N4: 999 | P4: 견적가 | Q4: TRUE
B5: =D5&"_"&F5&"_"&H5 -> M_BRX01_VM_BKT_15 | C5: Air-lift Type 그래뉼 생성장치 | D5: {=INDEX(기계코드!$D$4:$D$1022,MATCH(1,(C5=기계코드!$F$4:$F$1022)*1,0))} -> M_BRX01 | E5: (주)부강테크 | F5: {=INDEX(공급업체코드!$B$3:$B$1000,MATCH(1,(E5=공급업체코드!$D$3:$D$1000)*1,0))} -> VM_BKT | G5: AGR15 | H5: 15 | K5: 식 | M5: 공법 | N5: 999 | P5: 견적가 | Q5: TRUE
B6: =D6&"_"&F6&"_"&H6 -> M_BRX01_VM_BKT_20 | C6: Air-lift Type 그래뉼 생성장치 | D6: {=INDEX(기계코드!$D$4:$D$1022,MATCH(1,(C6=기계코드!$F$4:$F$1022)*1,0))} -> M_BRX01 | E6: (주)부강테크 | F6: {=INDEX(공급업체코드!$B$3:$B$1000,MATCH(1,(E6=공급업체코드!$D$3:$D$1000)*1,0))} -> VM_BKT | G6: AGR20 | H6: 20 | K6: 식 | M6: 공법 | N6: 999 | P6: 견적가 | Q6: TRUE
B8: =D8&"_"&F8&"_"&ROUNDDOWN(H8,0) -> M_BRX0201_VM_BKT_1594 | C8: ASBR | D8: {=INDEX(기계코드!$D$4:$D$1022,MATCH(1,(C8=기계코드!$F$4:$F$1022)*1,0))} -> M_BRX0201 | E8: (주)부강테크 | F8: {=INDEX(공급업체코드!$B$3:$B$1000,MATCH(1,(E8=공급업체코드!$D$3:$D$1000)*1,0))} -> VM_BKT | H8: 1594.4 | I8: 12.81 | J8: 15.47 | K8: 대 | M8: 공법 | N8: 0 | P8: 견적 필요 | Q8: TRUE
B9: =D9&"_"&F9&"_"&ROUNDDOWN(H9,0) -> M_BRX0201_VM_BKT_1895 | C9: ASBR | D9: {=INDEX(기계코드!$D$4:$D$1022,MATCH(1,(C9=기계코드!$F$4:$F$1022)*1,0))} -> M_BRX0201 | E9: (주)부강테크 | F9: {=INDEX(공급업체코드!$B$3:$B$1000,MATCH(1,(E9=공급업체코드!$D$3:$D$1000)*1,0))} -> VM_BKT | H9: 1895.2 | I9: 13.66 | J9: 16.17 | K9: 대 | M9: 공법 | N9: 0 | P9: 견적 필요 | Q9: TRUE
B10: =D10&"_"&F10&"_"&ROUNDDOWN(H10,0) -> M_BRX0201_VM_BKT_2234 | C10: ASBR | D10: {=INDEX(기계코드!$D$4:$D$1022,MATCH(1,(C10=기계코드!$F$4:$F$1022)*1,0))} -> M_BRX0201 | E10: (주)부강테크 | F10: {=INDEX(공급업체코드!$B$3:$B$1000,MATCH(1,(E10=공급업체코드!$D$3:$D$1000)*1,0))} -> VM_BKT | H10: 2234.4 | I10: 14.52 | J10: 16.87 | K10: 대 | M10: 공법 | N10: 0 | P10: 견적 필요 | Q10: TRUE
B11: =D11&"_"&F11&"_"&ROUNDDOWN(H11,0) -> M_BRX0201_VM_BKT_2327 | C11: ASBR | D11: {=INDEX(기계코드!$D$4:$D$1022,MATCH(1,(C11=기계코드!$F$4:$F$1022)*1,0))} -> M_BRX0201 | E11: (주)부강테크 | F11: {=INDEX(공급업체코드!$B$3:$B$1000,MATCH(1,(E11=공급업체코드!$D$3:$D$1000)*1,0))} -> VM_BKT | H11: 2327.2 | I11: 14.52 | J11: 17.57 | K11: 대 | M11: 공법 | N11: 0 | P11: 견적 필요 | Q11: TRUE
B12: =D12&"_"&F12&"_"&ROUNDDOWN(H12,0) -> M_BRX0201_VM_BKT_2711 | C12: ASBR | D12: {=INDEX(기계코드!$D$4:$D$1022,MATCH(1,(C12=기계코드!$F$4:$F$1022)*1,0))} -> M_BRX0201 | E12: (주)부강테크 | F12: {=INDEX(공급업체코드!$B$3:$B$1000,MATCH(1,(E12=공급업체코드!$D$3:$D$1000)*1,0))} -> VM_BKT | H12: 2711.2 | I12: 15.37 | J12: 18.27 | K12: 대 | M12: 공법 | N12: 0 | P12: 견적 필요 | Q12: TRUE
B13: =D13&"_"&F13&"_"&ROUNDDOWN(H13,0) -> M_BRX0201_VM_BKT_2815 | C13: ASBR | D13: {=INDEX(기계코드!$D$4:$D$1022,MATCH(1,(C13=기계코드!$F$4:$F$1022)*1,0))} -> M_BRX0201 | E13: (주)부강테크 | F13: {=INDEX(공급업체코드!$B$3:$B$1000,MATCH(1,(E13=공급업체코드!$D$3:$D$1000)*1,0))} -> VM_BKT | H13: 2815.2 | I13: 15.37 | J13: 18.97 | K13: 대 | M13: 공법 | N13: 0 | P13: 견적 필요 | Q13: TRUE
B14: =D14&"_"&F14&"_"&ROUNDDOWN(H14,0) -> M_BRX0201_VM_BKT_3251 | C14: ASBR | D14: {=INDEX(기계코드!$D$4:$D$1022,MATCH(1,(C14=기계코드!$F$4:$F$1022)*1,0))} -> M_BRX0201 | E14: (주)부강테크 | F14: {=INDEX(공급업체코드!$B$3:$B$1000,MATCH(1,(E14=공급업체코드!$D$3:$D$1000)*1,0))} -> VM_BKT | H14: 3251.2 | I14: 16.22 | J14: 19.67 | K14: 대 | M14: 공법 | N14: 0 | P14: 견적 필요 | Q14: TRUE
B15: =D15&"_"&F15&"_"&ROUNDDOWN(H15,0) -> M_BRX0201_VM_BKT_3733 | C15: ASBR | D15: {=INDEX(기계코드!$D$4:$D$1022,MATCH(1,(C15=기계코드!$F$4:$F$1022)*1,0))} -> M_BRX0201 | E15: (주)부강테크 | F15: {=INDEX(공급업체코드!$B$3:$B$1000,MATCH(1,(E15=공급업체코드!$D$3:$D$1000)*1,0))} -> VM_BKT | H15: 3733.6 | I15: 17.08 | J15: 20.37 | K15: 대 | M15: 공법 | N15: 0 | P15: 견적 필요 | Q15: TRUE
B16: =D16&"_"&F16&"_"&ROUNDDOWN(H16,0) -> M_BRX0201_VM_BKT_4256 | C16: ASBR | D16: {=INDEX(기계코드!$D$4:$D$1022,MATCH(1,(C16=기계코드!$F$4:$F$1022)*1,0))} -> M_BRX0201 | E16: (주)부강테크 | F16: {=INDEX(공급업체코드!$B$3:$B$1000,MATCH(1,(E16=공급업체코드!$D$3:$D$1000)*1,0))} -> VM_BKT | H16: 4256 | I16: 17.93 | J16: 21.07 | K16: 대 | M16: 공법 | N16: 0 | P16: 견적 필요 | Q16: TRUE
B17: =D17&"_"&F17&"_"&ROUNDDOWN(H17,0) -> M_BRX0201_VM_BKT_4828 | C17: ASBR | D17: {=INDEX(기계코드!$D$4:$D$1022,MATCH(1,(C17=기계코드!$F$4:$F$1022)*1,0))} -> M_BRX0201 | E17: (주)부강테크 | F17: {=INDEX(공급업체코드!$B$3:$B$1000,MATCH(1,(E17=공급업체코드!$D$3:$D$1000)*1,0))} -> VM_BKT | H17: 4828.8 | I17: 18.79 | J17: 21.77 | K17: 대 | M17: 공법 | N17: 0 | P17: 견적 필요 | Q17: TRUE
B18: =D18&"_"&F18&"_"&ROUNDDOWN(H18,0) -> M_BRX0201_VM_BKT_4984 | C18: ASBR | D18: {=INDEX(기계코드!$D$4:$D$1022,MATCH(1,(C18=기계코드!$F$4:$F$1022)*1,0))} -> M_BRX0201 | E18: (주)부강테크 | F18: {=INDEX(공급업체코드!$B$3:$B$1000,MATCH(1,(E18=공급업체코드!$D$3:$D$1000)*1,0))} -> VM_BKT | H18: 4984 | I18: 18.79 | J18: 22.47 | K18: 대 | M18: 공법 | N18: 0 | P18: 견적 필요 | Q18: TRUE
B19: =D19&"_"&F19&"_"&ROUNDDOWN(H19,0) -> M_BRX0201_VM_BKT_5784 | C19: ASBR | D19: {=INDEX(기계코드!$D$4:$D$1022,MATCH(1,(C19=기계코드!$F$4:$F$1022)*1,0))} -> M_BRX0201 | E19: (주)부강테크 | F19: {=INDEX(공급업체코드!$B$3:$B$1000,MATCH(1,(E19=공급업체코드!$D$3:$D$1000)*1,0))} -> VM_BKT | H19: 5784.8 | I19: 19.64 | J19: 23.87 | K19: 대 | M19: 공법 | N19: 0 | P19: 견적 필요 | Q19: TRUE
... B24: =D24&"_"&F24&"_"&ROUNDDOWN(H24,0) -> M_BRX0201_VM_BKT_10082 | C24: ASBR | D24: {=INDEX(기계코드!$D$4:$D$1022,MATCH(1,(C24=기계코드!$F$4:$F$1022)*1,0))} -> M_BRX0201 | E24: (주)부강테크 | F24: {=INDEX(공급업체코드!$B$3:$B$1000,MATCH(1,(E24=공급업체코드!$D$3:$D$1000)*1,0))} -> VM_BKT | H24: 10082.4 | I24: 23.91 | J24: 28.07 | K24: 대 | M24: 공법 | N24: 0 | P24: 견적 필요 | Q24: TRUE

Sheet 제어반
B1: 장비코드 | D1: 장비유형 | F1: 공급업체명 | G1: 모델명 | H1: 최소 시설용량 기준(㎥/d) | I1: 최대 시설용량 기준(㎥/d) | J1: 지수(Basin) | K1: 동력(kW) | L1: 총중량(kg) | M1: 단위 | N1: 호표(1) | O1: 분류 | P1: 단가(원) | Q1: 견적가(원) | R1: 단가출처 | S1: 사용여부 | T1: 장비설명 | U1: 단위시스템코드
B2: equipment_code | C2: 작업용 필드 | D2: equipment_type | E2: 작업용 필드 | F2: vendor_id | G2: model_number | H2: s_min_capacity_m3_d | I2: i_max_capacity_m3_d | J2: i_Basin_Basin | K2: s_power_kW | L2: s_total_wgt_kg | M2: s_unit_NONE | N2: s_primary_item_no_NONE | O2: s_remark_NONE | P2: o_unit_price_KRW | Q2: o_invoice_price_KRW | R2: o_price_reference | S2: is_active | T2: description | U2: unit_system_code
B3: =D3&"_"&F3&"_"&H3&"_"&I3 -> M_CTR0101_VM_BKT_0_100 | C3: SBR 가축분뇨 제어반 | D3: {=INDEX(기계코드!$D$4:$D$1022,MATCH(1,(C3=기계코드!$F$4:$F$1022)*1,0))} -> M_CTR0101 | E3: (주)부강테크 | F3: {=INDEX(공급업체코드!$B$3:$B$1000,MATCH(1,(E3=공급업체코드!$D$3:$D$1000)*1,0))} -> VM_BKT | G3: BCS가축분뇨 | H3: 0 | I3: 100 | M3: SET | O3: 공법 | P3: 275000000 | R3: 견적가 | S3: TRUE | T3: 2지 기준
B4: =D4&"_"&F4&"_"&H4&"_"&I4 -> M_CTR0102_VM_BKT_100_500 | C4: SBR 하수 제어반 | D4: {=INDEX(기계코드!$D$4:$D$1022,MATCH(1,(C4=기계코드!$F$4:$F$1022)*1,0))} -> M_CTR0102 | E4: (주)부강테크 | F4: {=INDEX(공급업체코드!$B$3:$B$1000,MATCH(1,(E4=공급업체코드!$D$3:$D$1000)*1,0))} -> VM_BKT | G4: BCS하수 | H4: 100 | I4: 500 | M4: SET | O4: 공법 | P4: 295000000 | R4: 견적가 | S4: TRUE | T4: 2지 기준
B5: =D5&"_"&F5&"_"&H5&"_"&I5 -> M_CTR0102_VM_BKT_200_1000 | C5: SBR 하수 제어반 | D5: {=INDEX(기계코드!$D$4:$D$1022,MATCH(1,(C5=기계코드!$F$4:$F$1022)*1,0))} -> M_CTR0102 | E5: (주)부강테크 | F5: {=INDEX(공급업체코드!$B$3:$B$1000,MATCH(1,(E5=공급업체코드!$D$3:$D$1000)*1,0))} -> VM_BKT | G5: BCS하수 | H5: 200 | I5: 1000 | M5: SET | O5: 공법 | P5: 275000000 | R5: 견적가 | S5: TRUE | T5: 2지 기준
B6: =D6&"_"&F6&"_"&H6&"_"&I6 -> M_CTR0102_VM_BKT_1000_5000 | C6: SBR 하수 제어반 | D6: {=INDEX(기계코드!$D$4:$D$1022,MATCH(1,(C6=기계코드!$F$4:$F$1022)*1,0))} -> M_CTR0102 | E6: (주)부강테크 | F6: {=INDEX(공급업체코드!$B$3:$B$1000,MATCH(1,(E6=공급업체코드!$D$3:$D$1000)*1,0))} -> VM_BKT | G6: BCS하수 | H6: 1000 | I6: 5000 | M6: SET | O6: 공법 | P6: 300000000 | R6: 견적가 | S6: TRUE | T6: 2지 기준
B7: =D7&"_"&F7&"_"&H7&"_"&I7 -> M_CTR0102_VM_BKT_500_5000 | C7: SBR 하수 제어반 | D7: {=INDEX(기계코드!$D$4:$D$1022,MATCH(1,(C7=기계코드!$F$4:$F$1022)*1,0))} -> M_CTR0102 | E7: (주)부강테크 | F7: {=INDEX(공급업체코드!$B$3:$B$1000,MATCH(1,(E7=공급업체코드!$D$3:$D$1000)*1,0))} -> VM_BKT | G7: BCS하수 | H7: 500 | I7: 5000 | M7: SET | O7: 공법 | P7: 485000000 | R7: 견적가 | S7: TRUE | T7: 4지 기준
B8: =D8&"_"&F8&"_"&H8&"_"&I8 -> M_CTR02_VM_BKT_500_5000 | C8: 종합제어반(계측기 미포함/전기공사비 별도) | D8: {=INDEX(기계코드!$D$4:$D$1022,MATCH(1,(C8=기계코드!$F$4:$F$1022)*1,0))} -> M_CTR02 | E8: (주)부강테크 | F8: {=INDEX(공급업체코드!$B$3:$B$1000,MATCH(1,(E8=공급업체코드!$D$3:$D$1000)*1,0))} -> VM_BKT | G8: BBF하수 | H8: 500 | I8: 5000 | M8: SET | O8: 공법 | P8: 342000000 | R8: 견적가 | S8: TRUE | T8: 4지 기준
B9: =D9&"_"&F9&"_"&H9&"_"&I9 -> M_CTR02_VM_BKT_5000_20000 | C9: 종합제어반(계측기 미포함/전기공사비 별도) | D9: {=INDEX(기계코드!$D$4:$D$1022,MATCH(1,(C9=기계코드!$F$4:$F$1022)*1,0))} -> M_CTR02 | E9: (주)부강테크 | F9: {=INDEX(공급업체코드!$B$3:$B$1000,MATCH(1,(E9=공급업체코드!$D$3:$D$1000)*1,0))} -> VM_BKT | G9: BBF하수 | H9: 5000 | I9: 20000 | M9: SET | O9: 공법 | P9: 390000000 | R9: 견적가 | S9: TRUE | T9: 8지 기준
B10: =D10&"_"&F10&"_"&H10&"_"&I10 -> M_CTR02_VM_BKT_20000_40000 | C10: 종합제어반(계측기 미포함/전기공사비 별도) | D10: {=INDEX(기계코드!$D$4:$D$1022,MATCH(1,(C10=기계코드!$F$4:$F$1022)*1,0))} -> M_CTR02 | E10: (주)부강테크 | F10: {=INDEX(공급업체코드!$B$3:$B$1000,MATCH(1,(E10=공급업체코드!$D$3:$D$1000)*1,0))} -> VM_BKT | G10: BBF하수 | H10: 20000 | I10: 40000 | M10: SET | O10: 공법 | P10: 450000000 | R10: 견적가 | S10: TRUE | T10: 12지 기준
B11: =D11&"_"&F11&"_"&I11 -> M_CTR0103_VM_BKT_99999 | C11: AMX 제어반 | D11: {=INDEX(기계코드!$D$4:$D$1022,MATCH(1,(C11=기계코드!$F$4:$F$1022)*1,0))} -> M_CTR0103 | E11: (주)부강테크 | F11: {=INDEX(공급업체코드!$B$3:$B$1000,MATCH(1,(E11=공급업체코드!$D$3:$D$1000)*1,0))} -> VM_BKT | G11: AMX 제어반 | I11: 99999 | M11: SET | O11: 공법 | P11: 333000000 | R11: 견적가 | S11: TRUE
B13: =D13&"_"&F13&"_"&J13 -> M_CTR0104_VM_BKT_1 | C13: AAD 제어반 | D13: {=INDEX(기계코드!$D$4:$D$1022,MATCH(1,(C13=기계코드!$F$4:$F$1022)*1,0))} -> M_CTR0104 | E13: (주)부강테크 | F13: {=INDEX(공급업체코드!$B$3:$B$1000,MATCH(1,(E13=공급업체코드!$D$3:$D$1000)*1,0))} -> VM_BKT | G13: AAD 제어반 | J13: 1 | M13: SET | O13: 공법 | P13: 293743000 | R13: 견적가 | S13: TRUE | T13: 1지 기준
B14: =D14&"_"&F14&"_"&J14 -> M_CTR0104_VM_BKT_2 | C14: AAD 제어반 | D14: {=INDEX(기계코드!$D$4:$D$1022,MATCH(1,(C14=기계코드!$F$4:$F$1022)*1,0))} -> M_CTR0104 | E14: (주)부강테크 | F14: {=INDEX(공급업체코드!$B$3:$B$1000,MATCH(1,(E14=공급업체코드!$D$3:$D$1000)*1,0))} -> VM_BKT | G14: AAD 제어반 | J14: 2 | M14: SET | O14: 공법 | P14: =$P$13*J14 -> 587486000 | R14: 견적가 | S14: TRUE | T14: =J14&"지 기준" -> 2지 기준
B15: =D15&"_"&F15&"_"&J15 -> M_CTR0104_VM_BKT_3 | C15: AAD 제어반 | D15: {=INDEX(기계코드!$D$4:$D$1022,MATCH(1,(C15=기계코드!$F$4:$F$1022)*1,0))} -> M_CTR0104 | E15: (주)부강테크 | F15: {=INDEX(공급업체코드!$B$3:$B$1000,MATCH(1,(E15=공급업체코드!$D$3:$D$1000)*1,0))} -> VM_BKT | G15: AAD 제어반 | J15: 3 | M15: SET | O15: 공법 | P15: =$P$13*J15 -> 881229000 | R15: 견적가 | S15: TRUE | T15: =J15&"지 기준" -> 3지 기준
B16: =D16&"_"&F16&"_"&J16 -> M_CTR0104_VM_BKT_4 | C16: AAD 제어반 | D16: {=INDEX(기계코드!$D$4:$D$1022,MATCH(1,(C16=기계코드!$F$4:$F$1022)*1,0))} -> M_CTR0104 | E16: (주)부강테크 | F16: {=INDEX(공급업체코드!$B$3:$B$1000,MATCH(1,(E16=공급업체코드!$D$3:$D$1000)*1,0))} -> VM_BKT | G16: AAD 제어반 | J16: 4 | M16: SET | O16: 공법 | P16: =$P$13*J16 -> 1174972000 | R16: 견적가 | S16: TRUE | T16: =J16&"지 기준" -> 4지 기준
B17: =D17&"_"&F17&"_"&J17 -> M_CTR0104_VM_BKT_5 | C17: AAD 제어반 | D17: {=INDEX(기계코드!$D$4:$D$1022,MATCH(1,(C17=기계코드!$F$4:$F$1022)*1,0))} -> M_CTR0104 | E17: (주)부강테크 | F17: {=INDEX(공급업체코드!$B$3:$B$1000,MATCH(1,(E17=공급업체코드!$D$3:$D$1000)*1,0))} -> VM_BKT | G17: AAD 제어반 | J17: 5 | M17: SET | O17: 공법 | P17: =$P$13*J17 -> 1468715000 | R17: 견적가 | S17: TRUE | T17: =J17&"지 기준" -> 5지 기준
B18: =D18&"_"&F18&"_"&J18 -> M_CTR0104_VM_BKT_6 | C18: AAD 제어반 | D18: {=INDEX(기계코드!$D$4:$D$1022,MATCH(1,(C18=기계코드!$F$4:$F$1022)*1,0))} -> M_CTR0104 | E18: (주)부강테크 | F18: {=INDEX(공급업체코드!$B$3:$B$1000,MATCH(1,(E18=공급업체코드!$D$3:$D$1000)*1,0))} -> VM_BKT | G18: AAD 제어반 | J18: 6 | M18: SET | O18: 공법 | P18: =$P$13*J18 -> 1762458000 | R18: 견적가 | S18: TRUE | T18: =J18&"지 기준" -> 6지 기준
B19: =D19&"_"&F19&"_"&J19 -> M_CTR0104_VM_BKT_7 | C19: AAD 제어반 | D19: {=INDEX(기계코드!$D$4:$D$1022,MATCH(1,(C19=기계코드!$F$4:$F$1022)*1,0))} -> M_CTR0104 | E19: (주)부강테크 | F19: {=INDEX(공급업체코드!$B$3:$B$1000,MATCH(1,(E19=공급업체코드!$D$3:$D$1000)*1,0))} -> VM_BKT | G19: AAD 제어반 | J19: 7 | M19: SET | O19: 공법 | P19: =$P$13*J19 -> 2056201000 | R19: 견적가 | S19: TRUE | T19: =J19&"지 기준" -> 7지 기준
B20: =D20&"_"&F20&"_"&J20 -> M_CTR0104_VM_BKT_8 | C20: AAD 제어반 | D20: {=INDEX(기계코드!$D$4:$D$1022,MATCH(1,(C20=기계코드!$F$4:$F$1022)*1,0))} -> M_CTR0104 | E20: (주)부강테크 | F20: {=INDEX(공급업체코드!$B$3:$B$1000,MATCH(1,(E20=공급업체코드!$D$3:$D$1000)*1,0))} -> VM_BKT | G20: AAD 제어반 | J20: 8 | M20: SET | O20: 공법 | P20: =$P$13*J20 -> 2349944000 | R20: 견적가 | S20: TRUE | T20: =J20&"지 기준" -> 8지 기준

Sheet 교반기
B1: 장비코드 | D1: 장비유형 | F1: 공급업체명 | G1: 모델명 | H1: 회전수(rpm) | I1: 교반용적(㎥) | J1: 동력(kW) | K1: 기동방식 | L1: 정격전압(V) | M1: 효율(%) | N1: 역률(%) | O1: 수용율(%) | P1: 총중량(kg) | Q1: 단위 | R1: 호표(1) | S1: 분류 | T1: 단가(원) | U1: 견적가(원) | V1: 단가출처 | W1: 사용여부 | X1: 장비설명 | Y1: 단위시스템코드
B2: equipment_code | C2: 작업용 필드 | D2: equipment_type | E2: 작업용 필드 | F2: vendor_id | G2: model_number | H2: s_no_revolutions_rpm | I2: i_agitated_volume_m3 | J2: s_power_kW | K2: s_ctrl_method | L2: s_rated_volt_V | M2: s_efficiency_percent | N2: s_pwr_factor_percent | O2: s_demand_factor_percent | P2: s_total_wgt_kg | Q2: s_unit_NONE | R2: s_primary_item_no_NONE | S2: s_remark_NONE | T2: o_unit_price_KRW | U2: o_invoice_price_KRW | V2: o_price_reference | W2: is_active | X2: description | Y2: unit_system_code
A3: SMS-044-2B | B3: =D3&"_"&F3&"_"&I3 -> M_AGT0602_VM_SAMJIN_45 | C3: 수중횡축 프로펠러형 (인양장치, 모니터링유니트 포함) | D3: {=INDEX(기계코드!$D$4:$D$1022,MATCH(1,(C3=기계코드!$F$4:$F$1022)*1,0))} -> M_AGT0602 | E3: 삼진공업 | F3: {=INDEX(공급업체코드!$B$3:$B$1000,MATCH(1,(E3=공급업체코드!$D$3:$D$1000)*1,0))} -> VM_SAMJIN | G3: SMS-044-2B | H3: 1800 | I3: 45 | J3: 0.4 | K3: S_SYS01 | L3: 380 | M3: 0.65 | N3: 0.9 | O3: 60 | P3: 11 | Q3: EA | R3: =IF(P3<500,1,IF(P3<1000,2,IF(P3<5000,3,4))) -> 1 | S3: 일반 | T3: 999 | V3: 견적 필요 | W3: TRUE
A4: SMS-084-2B | B4: =D4&"_"&F4&"_"&I4 -> M_AGT0602_VM_SAMJIN_75 | C4: 수중횡축 프로펠러형 (인양장치, 모니터링유니트 포함) | D4: {=INDEX(기계코드!$D$4:$D$1022,MATCH(1,(C4=기계코드!$F$4:$F$1022)*1,0))} -> M_AGT0602 | E4: 삼진공업 | F4: {=INDEX(공급업체코드!$B$3:$B$1000,MATCH(1,(E4=공급업체코드!$D$3:$D$1000)*1,0))} -> VM_SAMJIN | G4: SMS-084-2B | H4: 1800 | I4: 75 | J4: 0.75 | K4: S_SYS01 | L4: 380 | M4: 0.835 | N4: 0.9 | O4: 60 | P4: 11 | Q4: EA | R4: =IF(P4<500,1,IF(P4<1000,2,IF(P4<5000,3,4))) -> 1 | S4: 일반 | T4: 999 | V4: 견적 필요 | W4: TRUE
A5: SMS-154-3B | B5: =D5&"_"&F5&"_"&I5 -> M_AGT0602_VM_SAMJIN_110 | C5: 수중횡축 프로펠러형 (인양장치, 모니터링유니트 포함) | D5: {=INDEX(기계코드!$D$4:$D$1022,MATCH(1,(C5=기계코드!$F$4:$F$1022)*1,0))} -> M_AGT0602 | E5: 삼진공업 | F5: {=INDEX(공급업체코드!$B$3:$B$1000,MATCH(1,(E5=공급업체코드!$D$3:$D$1000)*1,0))} -> VM_SAMJIN | G5: SMS-154-3B | H5: 1800 | I5: 110 | J5: 1.5 | K5: S_SYS01 | L5: 380 | M5: 0.865 | N5: 0.9 | O5: 60 | P5: 11 | Q5: EA | R5: =IF(P5<500,1,IF(P5<1000,2,IF(P5<5000,3,4))) -> 1 | S5: 일반 | T5: 17000000 | V5: 물가자료25년10월호1362Page | W5: TRUE
A6: SMS-158-3B | B6: =D6&"_"&F6&"_"&I6 -> M_AGT0602_VM_SAMJIN_150 | C6: 수중횡축 프로펠러형 (인양장치, 모니터링유니트 포함) | D6: {=INDEX(기계코드!$D$4:$D$1022,MATCH(1,(C6=기계코드!$F$4:$F$1022)*1,0))} -> M_AGT0602 | E6: 삼진공업 | F6: {=INDEX(공급업체코드!$B$3:$B$1000,MATCH(1,(E6=공급업체코드!$D$3:$D$1000)*1,0))} -> VM_SAMJIN | G6: SMS-224-3B | H6: 1800 | I6: 150 | J6: 2.2 | K6: S_SYS01 | L6: 380 | M6: 0.895 | N6: 0.9 | O6: 60 | P6: 11 | Q6: EA | R6: =IF(P6<500,1,IF(P6<1000,2,IF(P6<5000,3,4))) -> 1 | S6: 일반 | T6: 10500000 | V6: 물가자료25년10월호1362Page | W6: TRUE
