Workbook

Sheet 계측기코드
B1: system_code | C1: code_group | D1: code_key | E1: parent_key | F1: code_value | G1: code_value_en | H1: code_level | I1: is_leaf | J1: code_order | K1: iso15926_rdl | L1: description
B2: WAI_DESIGN_APP | C2: INSTRUMENT | D2: INSTRMT | F2: 계측기 | G2: Instruments | H2: 1 | J2: 1
B3: WAI_DESIGN_APP | C3: WATER_GAUGE | D3: I_WTGG | E3: INSTRMT | F3: 수위계 | G3: Water Gauge | H3: 2 | J3: 1
B4: WAI_DESIGN_APP | C4: WATER_GAUGE | D4: I_WTG00 | E4: I_WTGG | F4: 미분류 | G4: Unclassified | H4: 3 | I4: TRUE | J4: 1
B5: WAI_DESIGN_APP | C5: WATER_GAUGE | D5: I_WTG01 | E5: I_WTGG | F5: 초음파식 수위계 | G5: 초음파식 수위계 | H5: 3 | I5: TRUE | J5: 2
B6: WAI_DESIGN_APP | C6: WATER_GAUGE | D6: I_WTG02 | E6: I_WTGG | F6: 레이더식 수위계 | G6: 레이더식 수위계 | H6: 3 | I6: TRUE | J6: 3
B7: WAI_DESIGN_APP | C7: WATER_GAUGE | D7: I_WTG03 | E7: I_WTGG | F7: 플로트식 수위계 | G7: 플로트식 수위계 | H7: 3 | I7: TRUE | J7: 4
B8: WAI_DESIGN_APP | C8: WATER_GAUGE | D8: I_WTG04 | E8: I_WTGG | F8: 오뚜기식 수위스위치 | G8: 오뚜기식 수위스위치 | H8: 3 | I8: TRUE | J8: 5
B9: WAI_DESIGN_APP | C9: WATER_GAUGE | D9: I_WTG05 | E9: I_WTGG | F9: 플로트식 수위스위치 | G9: 플로트식 수위스위치 | H9: 3 | I9: TRUE | J9: 6
B10: WAI_DESIGN_APP | C10: WATER_GAUGE | D10: I_WTG06 | E10: I_WTGG | F10: 전극식 수위치 | G10: 전극식 수위치 | H10: 3 | I10: TRUE | J10: 7
B11: WAI_DESIGN_APP | C11: FLOW_METER | D11: I_FLMT | E11: INSTRMT | F11: 유량계 | G11: Flow Meter | H11: 2 | J11: 2
B12: WAI_DESIGN_APP | C12: FLOW_METER | D12: I_FLM00 | E12: I_FLMT | F12: 미분류 유량계 | G12: Unclassified | H12: 3 | I12: TRUE | J12: 1
B13: WAI_DESIGN_APP | C13: FLOW_METER | D13: I_FLM01 | E13: I_FLMT | F13: 전자식 유량계 | G13: 전자식 유량계 | H13: 3 | I13: TRUE | J13: 2
B14: WAI_DESIGN_APP | C14: FLOW_METER | D14: I_FLM02 | E14: I_FLMT | F14: 초음파식 유량계 | G14: 초음파식 유량계 | H14: 3 | I14: TRUE | J14: 3
B15: WAI_DESIGN_APP | C15: FLOW_METER | D15: I_FLM03 | E15: I_FLMT | F15: 가스식 유량계 | G15: 가스식 유량계 | H15: 3 | I15: FALSE | J15: 4
B16: WAI_DESIGN_APP | C16: FLOW_METER | D16: I_FLM04 | E16: I_FLMT | F16: 기계식 유량계 | G16: 기계식 유량계 | H16: 3 | I16: FALSE | J16: 5
B17: WAI_DESIGN_APP | C17: FLOW_METER | D17: I_FLM05 | E17: I_FLMT | F17: 차압식 유량계 | G17: 차압식 유량계 | H17: 3 | I17: FALSE | J17: 6
B18: WAI_DESIGN_APP | C18: FLOW_METER | D18: I_FLM06 | E18: I_FLMT | F18: 질량 유량계 | G18: 질량 유량계 | H18: 3 | I18: TRUE | J18: 7
B19: WAI_DESIGN_APP | C19: PH_METER | D19: I_PHMT | E19: INSTRMT | F19: pH 측정기 | G19: pH Meter | H19: 2 | J19: 3
B20: WAI_DESIGN_APP | C20: PH_METER | D20: I_PHM00 | E20: I_PHMT | F20: 미분류 pH 측정기 | G20: Unclassified | H20: 3 | I20: TRUE | J20: 1
B21: WAI_DESIGN_APP | C21: PH_METER | D21: I_PHM01 | E21: I_PHMT | F21: 유리전극식 pH측정기 | G21: 유리전극식 pH측정기 | H21: 3 | I21: TRUE | J21: 2
B22: WAI_DESIGN_APP | C22: PH_METER | D22: I_PHM02 | E22: I_PHMT | F22: 고정전극식 PH측정기 | G22: 고정전극식 PH측정기 | H22: 3 | I22: FALSE | J22: 3
B23: WAI_DESIGN_APP | C23: ORP_METER | D23: I_ORPM | E23: INSTRMT | F23: ORP 측정기 | G23: ORP Meter | H23: 2 | J23: 4
B24: WAI_DESIGN_APP | C24: ORP_METER | D24: I_ORP00 | E24: I_ORPM | F24: 미분류 ORP 측정기 | G24: Unclassified | H24: 3 | I24: TRUE | J24: 1
B25: WAI_DESIGN_APP | C25: ORP_METER | D25: I_ORP01 | E25: I_ORPM | F25: 금속전극식 ORP 측정기 | G25: 금속전극식 ORP 측정기 | H25: 3 | I25: TRUE | J25: 2
B26: WAI_DESIGN_APP | C26: ORP_METER | D26: I_ORP02 | E26: I_ORPM | F26: 고정전극식 ORP 측정기 | G26: 고정전극식 ORP 측정기 | H26: 3 | I26: TRUE | J26: 3
B27: WAI_DESIGN_APP | C27: DO_METER | D27: I_DOMT | E27: INSTRMT | F27: DO 측정기 | G27: DO Meter | H27: 2 | J27: 5
B28: WAI_DESIGN_APP | C28: DO_METER | D28: I_DOM00 | E28: I_DOMT | F28: 미분류 DO 측정기 | G28: Unclassified | H28: 3 | I28: TRUE | J28: 1
B29: WAI_DESIGN_APP | C29: DO_METER | D29: I_DOM01 | E29: I_DOMT | F29: 광학식 DO 측정기 | G29: 광학식 DO 측정기 | H29: 3 | I29: TRUE | J29: 2
B30: WAI_DESIGN_APP | C30: DO_METER | D30: I_DOM02 | E30: I_DOMT | F30: 갈바닉식 DO 측정기 | G30: 갈바닉식 DO 측정기 | H30: 3 | I30: FALSE | J30: 3
B31: WAI_DESIGN_APP | C31: DO_METER | D31: I_DOM03 | E31: I_DOMT | F31: 폴라로그래픽식 DO 측정기 | G31: 폴라로그래픽식 DO 측정기 | H31: 3 | I31: TRUE | J31: 4
B32: WAI_DESIGN_APP | C32: PRESS_GAUGE | D32: I_PRESS | E32: INSTRMT | F32: 압력계 | G32: Pressure Gauge | H32: 2 | J32: 6
B33: WAI_DESIGN_APP | C33: PRESS_GAUGE | D33: I_PRSS00 | E33: I_PRESS | F33: 미분류 압력계 | G33: Unclassified | H33: 3 | I33: TRUE | J33: 1
B34: WAI_DESIGN_APP | C34: PRESS_GAUGE | D34: I_PRSS01 | E34: I_PRESS | F34: 전자식 압력계 | G34: 전자식 압력계 | H34: 3 | I34: FALSE | J34: 2
B35: WAI_DESIGN_APP | C35: PRESS_GAUGE | D35: I_PRSS02 | E35: I_PRESS | F35: 격막식 압력계 | G35: 격막식 압력계 | H35: 3 | I35: TRUE | J35: 3
B36: WAI_DESIGN_APP | C36: PRESS_GAUGE | D36: I_PRSS03 | E36: I_PRESS | F36: 기계식 압력계 | G36: 기계식 압력계 | H36: 3 | I36: FALSE | J36: 4
B37: WAI_DESIGN_APP | C37: PRESS_GAUGE | D37: I_PRSS04 | E37: I_PRESS | F37: 디지털식 압력계 | G37: 디지털식 압력계 | H37: 3 | I37: FALSE | J37: 5
B38: WAI_DESIGN_APP | C38: PRESS_GAUGE | D38: I_PRSS05 | E38: I_PRESS | F38: 광섬유식 부압력계 | G38: 광섬유식 부압력계 | H38: 3 | I38: FALSE | J38: 6
B39: WAI_DESIGN_APP | C39: THERMO | D39: I_THMT | E39: INSTRMT | F39: 온도계 | G39: Thermometer | H39: 2 | J39: 7
B40: WAI_DESIGN_APP | C40: THERMOMETER | D40: I_THM00 | E40: I_THMT | F40: 미분류 온도계 | G40: Unclassified | H40: 3 | I40: TRUE | J40: 1
...

Sheet 재질(NEW)
B1: system_code | C1: code_group | D1: code_key | E1: parent_key | F1: code_value | G1: code_value_en | H1: code_level | I1: is_leaf | J1: code_order | K1: iso15926_rdl | L1: description
B2: WAI_DESIGN_APP | C2: MATERIALS | D2: MATER | F2: 재질 | G2: Materials | H2: 1 | J2: 1
B3: WAI_DESIGN_APP | C3: MATER_STEEL | D3: MATER_STL | E3: MATER | F3: 강재(미분류) | G3: STL | H3: 2 | J3: 1 | L3: Steel | M3: STEEL 전체 표시 약어 | N3: 한국규격(KS)에 의한 표시기호(symbolic notation)
B4: WAI_DESIGN_APP | C4: MATER_CARBON_STEEL | D4: MATER_CS | E4: MATER | F4: 탄소강 | G4: CS | H4: 2 | J4: 2 | L4: Carbon Steel
B5: WAI_DESIGN_APP | C5: MATER_CARBON_STEEL | D5: CS_SF | E5: MATER_CS | F5: SF | G5: Carbon Steel Forgings for General Use | H5: 3 | J5: 1 | L5: 탄소강 단강품(SF)
B6: WAI_DESIGN_APP | C6: MATER_CARBON_STEEL | D6: SF440A | E6: CS_SF | F6: SF440A | G6: SF440A | H6: 4 | I6: TRUE | J6: 1 | L6: 탄소강 단강품(SF440A) | M6: 밸브 재질
B7: WAI_DESIGN_APP | C7: MATER_CARBON_STEEL | D7: CS_SM | E7: MATER_CS | F7: SM | G7: Steel Machine Carbon | H7: 3 | J7: 2 | L7: 기계 구조용 탄소강재(SM)
B8: WAI_DESIGN_APP | C8: MATER_CARBON_STEEL | D8: SM45C | E8: CS_SM | F8: SM45C | G8: SM45C | H8: 4 | I8: TRUE | J8: 1 | L8: 기계 구조용 탄소강재(SM45C) | M8: 모노펌프부품 재질
B9: WAI_DESIGN_APP | C9: MATER_CAST_IRON | D9: MATER_CI | E9: MATER | F9: 주철 | G9: CI | H9: 2 | J9: 3 | L9: Cast Iron
B10: WAI_DESIGN_APP | C10: MATER_CAST_IRON | D10: CI_GC | E10: MATER_CI | F10: 회주철(GC) | G10: Gray Cast Iron | H10: 3 | J10: 1 | L10: 회주철(GC)
B11: WAI_DESIGN_APP | C11: MATER_CAST_IRON | D11: GC200 | E11: CI_GC | F11: GC200 | G11: Gray Cast Iron(200) | H11: 4 | I11: TRUE | J11: 1 | L11: 회주철(GC 200) | M11: 스프르트펌프 재질
B12: WAI_DESIGN_APP | C12: MATER_CAST_IRON | D12: GC250 | E12: CI_GC | F12: GC250 | G12: Gray Cast Iron(250) | H12: 4 | I12: TRUE | J12: 2 | L12: 회주철(GC 250) | M12: 일축스크류(모노)펌프 재질
B13: WAI_DESIGN_APP | C13: MATER_CAST_IRON | D13: CI_GCD | E13: MATER_CI | F13: GCD | G13: Graphite Casting Ductile | H13: 3 | J13: 2 | L13: 구상흑연주철(GCD)
B14: WAI_DESIGN_APP | C14: MATER_CAST_IRON | D14: GCD450 | E14: CI_GCD | F14: GCD450 | G14: Graphite Casting Ductile(450) | H14: 4 | I14: TRUE | J14: 1 | L14: 구상흑연주철(GCD 450) | M14: 밸브 재질
B15: WAI_DESIGN_APP | C15: MATER_CAST_STEEL | D15: MATER_CAST | E15: MATER | F15: 주강 | G15: Cast Steel | H15: 2 | J15: 4
B16: WAI_DESIGN_APP | C16: MATERIALS_KS | D16: SCPH | E16: MATER_CAST | F16: SCPH | G16: Steel Casting Pressure High Temperature | H16: 3 | J16: 1 | L16: 고온고압용 주강(SCPH)
B17: WAI_DESIGN_APP | C17: MATERIALS_KS | D17: SCPH2 | E17: SCPH | F17: SCPH2 | G17: Steel Casting Pressure High Temperature(2) | H17: 4 | I17: TRUE | J17: 1 | L17: 고온고압용 주강(SCPH2)
B18: WAI_DESIGN_APP | C18: MATERIALS_KS | D18: SSC | E18: MATER_CAST | F18: SSC | G18: Stainless Steel Casting | H18: 3 | J18: 2 | L18: 스테인리스 주강(SSC/SCS)
B19: WAI_DESIGN_APP | C19: MATERIALS_KS | D19: SSC13 | E19: SSC | F19: SSC13 | G19: Stainless Steel Casting(13) | H19: 4 | I19: TRUE | J19: 1 | L19: 스테인리스 주강(SSC13/SCS13) | M19: 밸브, 스프르트펌프 재질
B20: WAI_DESIGN_APP | C20: MATER_TOOL | D20: MATER_TS | E20: MATER | F20: 공구강 | G20: TS | H20: 2 | J20: 5 | L20: Tool Steel(TS)
B21: WAI_DESIGN_APP | C21: MATERIALS_KS | D21: STD | E21: MATER_TS | F21: STD | G21: Steel Tool Dies | H21: 3 | J21: 1 | L21: 합금공구강(STD)
B22: WAI_DESIGN_APP | C22: MATERIALS_KS | D22: STD11 | E22: STD | F22: STD11 | G22: Steel Tool Dies(D2) | H22: 4 | I22: TRUE | J22: 1 | L22: 합금공구강(STD11) | M22: 모노펌프부품 재질
B23: WAI_DESIGN_APP | C23: MATERIALS_KS | D23: STD11_STS304 | E23: STD | F23: STD11/STS304 | G23: STD11/STS304 | H23: 4 | I23: TRUE | J23: 2 | L23: 합금공구강(STD11/STS304) | M23: 모노펌프부품 재질
B24: WAI_DESIGN_APP | C24: MATER_STAINLESS | D24: MATER_SS | E24: MATER | F24: 스테인리스 | G24: SS | H24: 2 | J24: 6 | L24: Stainless Steel(SS)
B25: WAI_DESIGN_APP | C25: MATERIALS_KS | D25: STS | E25: MATER_SS | F25: 스테인리스강(STS) | G25: Steel Type Stainless | H25: 3 | J25: 1
B26: WAI_DESIGN_APP | C26: MATERIALS_KS | D26: STS304 | E26: STS | F26: STS304 | G26: Stainless Steel(304SS) | H26: 4 | I26: TRUE | J26: 1 | M26: 모노펌프부품 재질
B27: WAI_DESIGN_APP | C27: MATERIALS_KS | D27: STS304L | E27: STS | F27: STS304L | G27: Stainless Steel(304L) Low-carbon | H27: 4 | I27: TRUE | J27: 2 | L27: STS304L 저탄소
B28: WAI_DESIGN_APP | C28: MATERIALS_KS | D28: STS304_HCr | E28: STS | F28: STS304 HCr | G28: Stainless Steel(304) High-chromium | H28: 4 | I28: TRUE | J28: 3 | L28: STS304 고크롬 | M28: 모노펌프부품 재질
B29: WAI_DESIGN_APP | C29: MATERIALS_KS | D29: STS310S | E29: STS | F29: STS310S | G29: Stainless Steel(310S) Low-carbon | H29: 4 | I29: TRUE | J29: 4 | L29: STS310S 저탄소
B30: WAI_DESIGN_APP | C30: MATERIALS_KS | D30: STS316 | E30: STS | F30: STS316 | G30: Stainless Steel(316SS) Molybdenum | H30: 4 | I30: TRUE | J30: 5 | L30: STS316 몰리브덴
B31: WAI_DESIGN_APP | C31: MATERIALS_KS | D31: STS316L | E31: STS | F31: STS316L | G31: Stainless Steel(316L) Molybdenum Low-carbon | H31: 4 | I31: TRUE | J31: 6 | L31: STS316L 몰리브덴 저탄소 | M31: 모노펌프부품 재질
B32: WAI_DESIGN_APP | C32: MATER_ALLOY | D32: MATER_ALLOY | E32: MATER | F32: 합금강 | G32: Alloy Steel | H32: 2 | J32: 7 | L32: 한국규격(KS)에 의한 표시기호(symbolic notation)
B33: WAI_DESIGN_APP | C33: MATERIALS_KS | D33: SNCM | E33: MATER_ALLOY | F33: 니켈 크롬 몰리브덴강(SNCM) | G33: Steel Nickel Chromium Molybdenum | H33: 3 | J33: 1
B34: WAI_DESIGN_APP | C34: MATERIALS_KS | D34: SNCM21 | E34: SNCM | F34: SNCM21 | G34: Steel Nickel Chromium Molybdenum(21) | H34: 4 | I34: TRUE | J34: 1 | M34: 모노펌프부품 재질
B35: WAI_DESIGN_APP | C35: MATERIALS_COPPER | D35: MATER_BRONZE | E35: MATER | F35: 청동 | G35: Bronze | H35: 2 | I35: TRUE | J35: 9
B36: WAI_DESIGN_APP | C36: MATERIALS_RUBBER | D36: MATER_RUBBER | E36: MATER | F36: 고무 | G36: Rubber | H36: 2 | J36: 10
B37: WAI_DESIGN_APP | C37: MATERIALS_RUBBER | D37: NBR | E37: MATER_RUBBER | F37: 니트릴 고무(NBR) | G37: Nitrile Butadiene Rubber | H37: 3 | I37: TRUE | J37: 1 | M37: 모노펌프부품 재질
B38: WAI_DESIGN_APP | C38: MATERIALS_RUBBER | D38: NBR_EPDM | E38: MATER_RUBBER | F38: NBR/EPDM | G38: NBR/EPDM | H38: 3 | I38: TRUE | J38: 2 | M38: 모노펌프부품 재질
B39: WAI_DESIGN_APP | C39: MATERIALS_RUBBER | D39: EPDM | E39: MATER_RUBBER | F39: 에틸렌 프로필렌 고무(EPDM) | G39: Rubber, ethylene-propylene-diene(EPDM) | H39: 3 | I39: TRUE | J39: 3 | M39: 모노펌프부품 재질
B40: WAI_DESIGN_APP | C40: MATERIALS_RUBBER | D40: FKM | E40: MATER_RUBBER | F40: 불소화 엘라스토머(FKM) | G40: Fluoropolymer | H40: 3 | J40: 4
...

Sheet 공급업체코드
B2: vendor_id | C2: vendor_name_en | D2: vendor_name_kr
B3: VM_0000 | C3: Non-designated company | D3: 미지정업체
B4: VM_BKT | C4: BKT | D4: (주)부강테크
B5: VM_BKT_TM | C5: BKT/TM | D5: (주)부강테크/터보맥스
B6: VM_BKT_CD_VM | C6: BKT/CS | D6: (주)부강테크/창신
B7: VM_BKT_SJ | C7: BKT/SJ | D7: (주)부강테크/삼진
B8: VM_BKT_HS | C8: BKT/HS | D8: (주)부강테크/한신테크노
B9: VM_BUMHAN | C9: Bumhan | D9: 범한
B10: VM_CS_IND | C10: Cheonsei | D10: 천세산업(주)
B11: VM_CB_ENG | C11: Cheonboe Engineering | D11: 천보엔지니어링
B12: VM_CEIL_ELC | C12: Cheil electric | D12: 제일일렉트릭
B13: VM_DH_ENG | C13: Donghai Engineering | D13: 동해엔지니어링
... B112: VM_HACH_KR | C112: Hach Korea, LLC | D112: 하크코리아(유)

Sheet 수위계
B1: 장비코드 | D1: 장비유형 | F1: 공급업체명 | G1: 모델명 | H1: 최대 측정 범위 (m) | I1: 보호등급 | J1: 센서재질 | K1: 단위 | L1: 단가(원) | M1: 견적가(원) | N1: 단가출처 | O1: 사용여부 | P1: 품명 | Q1: 규격 | R1: 장비설명 | S1: 단위시스템코드
B2: equipment_code | C2: 작업용 필드 | D2: equipment_type | E2: 작업용 필드 | F2: vendor_id | G2: model_number | H2: i_meas_range_m | I2: s_ingress_protection_NONE | J2: s_sensor_material_NONE | K2: s_unit_NONE | L2: o_unit_price_KRW | M2: o_invoice_price_KRW | N2: o_price_reference | O2: is_active | P2: s_productnm_NONE | Q2: s_easpecific_NONE | R2: description | S2: unit_system_code
B3: =D3&"_"&F3&"_"&H3 -> I_WTG01_VM_WESS_GLOB_15 | C3: 초음파식 수위계 | D3: {=INDEX(계측기코드!$D$4:$D$189,MATCH(1,(C3=계측기코드!$F$4:$F$190)*1,0))} -> I_WTG01 | E3: 웨스글로벌(주) | F3: {=INDEX(공급업체코드!$B$66:$B$150,MATCH(1,(E3=공급업체코드!$D$66:$D$150)*1,0))} -> VM_WESS_GLOB | G3: LEV100-S | H3: 15 | I3: 68 | J3: PVC | K3: EA | L3: 3800000 | N3: 물가자료25년9월호1401page | O3: TRUE | P3: =C3 -> 초음파식 수위계 | R3: 초음파 수위계 (분리형) LEV100-S(싱글형) 15m
B4: =D4&"_"&F4&"_"&H4 -> I_WTG02_VM_HITROL_CO_20 | C4: 레이더식 수위계 | D4: {=INDEX(계측기코드!$D$4:$D$189,MATCH(1,(C4=계측기코드!$F$4:$F$190)*1,0))} -> I_WTG02 | E4: 하이트롤 | F4: {=INDEX(공급업체코드!$B$66:$B$150,MATCH(1,(E4=공급업체코드!$D$66:$D$150)*1,0))} -> VM_HITROL_CO | G4: HWP-200 | H4: 20 | K4: EA | L4: 5310000 | N4: 물가자료25년10월호861page | O4: TRUE | P4: =C4 -> 레이더식 수위계 | R4: 레이다 수위 전송기 (케이블 몰딩 타입)
B5: =D5&"_"&F5&"_"&H5 -> I_WTG03_VM_HITROL_CO_7.5 | C5: 플로트식 수위계 | D5: {=INDEX(계측기코드!$D$4:$D$189,MATCH(1,(C5=계측기코드!$F$4:$F$190)*1,0))} -> I_WTG03 | E5: 하이트롤 | F5: {=INDEX(공급업체코드!$B$66:$B$150,MATCH(1,(E5=공급업체코드!$D$66:$D$150)*1,0))} -> VM_HITROL_CO | G5: HT-100F | H5: 7.5 | I5: 54 | J5: STS316L | K5: EA | L5: 2530000 | N5: 물가자료25년10월호861page | O5: TRUE | P5: =C5 -> 플로트식 수위계 | R5: 플로트식 수위전송기
B6: =D6&"_"&F6&"_"&H6 -> I_WTG04_VM_HITROL_CO_6 | C6: 오뚜기식 수위스위치 | D6: {=INDEX(계측기코드!$D$4:$D$189,MATCH(1,(C6=계측기코드!$F$4:$F$190)*1,0))} -> I_WTG04 | E6: 하이트롤 | F6: {=INDEX(공급업체코드!$B$66:$B$150,MATCH(1,(E6=공급업체코드!$D$66:$D$150)*1,0))} -> VM_HITROL_CO | G6: HQ-66 | H6: 6 | I6: 54 | J6: ABS | K6: EA | L6: 540000 | N6: 물가자료25년10월호861page | O6: TRUE | P6: =C6 -> 오뚜기식 수위스위치 | R6: 오뚜기식 수위스위치 (2-접점)
B7: =D7&"_"&F7&"_"&H7 -> I_WTG05_VM_HITROL_CO_4 | C7: 플로트식 수위스위치 | D7: {=INDEX(계측기코드!$D$4:$D$189,MATCH(1,(C7=계측기코드!$F$4:$F$190)*1,0))} -> I_WTG05 | E7: 하이트롤 | F7: {=INDEX(공급업체코드!$B$66:$B$150,MATCH(1,(E7=공급업체코드!$D$66:$D$150)*1,0))} -> VM_HITROL_CO | G7: HR-30S | H7: 4 | I7: 65 | J7: STS316L | K7: EA | L7: 1310000 | N7: 물가자료25년10월호861page | O7: TRUE | P7: =C7 -> 플로트식 수위스위치 | R7: 플로트식 수위스위치 (2-접점), STS316L, TEFLON, PVC
B8: =D8&"_"&F8&"_"&H8 -> I_WTG06_VM_HITROL_CO_4 | C8: 전극식 수위치 | D8: {=INDEX(계측기코드!$D$4:$D$189,MATCH(1,(C8=계측기코드!$F$4:$F$190)*1,0))} -> I_WTG06 | E8: 하이트롤 | F8: {=INDEX(공급업체코드!$B$66:$B$150,MATCH(1,(E8=공급업체코드!$D$66:$D$150)*1,0))} -> VM_HITROL_CO | G8: HE-5V | H8: 4 | I8: 54 | J8: PVDF | K8: EA | L8: 930000 | N8: 물가자료25년10월호861page | O8: TRUE | P8: =C8 -> 전극식 수위치 | R8: 전극식 수위스위치 (4-접점)

Sheet 유량계
B1: 장비코드 | D1: 장비유형 | F1: 공급업체명 | G1: 모델명 | H1: 관경 (mm) | I1: 보호등급 | J1: 라이닝재질 | K1: 단위 | L1: 단가(원) | M1: 견적가(원) | N1: 단가출처 | O1: 사용여부 | P1: 품명 | Q1: 규격 | R1: 장비설명 | S1: 단위시스템코드
A2: 3D파일 유형명 | B2: equipment_code | C2: 작업용 필드 | D2: equipment_type | E2: 작업용 필드 | F2: vendor_id | G2: model_number | H2: i_dia_mm | I2: s_ingress_protection_NONE | J2: s_lining_material_NONE | K2: s_unit_NONE | L2: o_unit_price_KRW | M2: o_invoice_price_KRW | N2: o_price_reference | O2: is_active | P2: s_productnm_NONE | Q2: s_easpecific_NONE | R2: description | S2: unit_system_code
B3: =D3&"_"&F3&"_"&H3 -> I_FLM01_VM_WINTEC_CORP_3 | C3: 전자식 유량계 | D3: {=INDEX(계측기코드!$D$4:$D$189,MATCH(1,(C3=계측기코드!$F$4:$F$190)*1,0))} -> I_FLM01 | E3: 윈텍 | F3: {=INDEX(공급업체코드!$B$66:$B$150,MATCH(1,(E3=공급업체코드!$D$66:$D$150)*1,0))} -> VM_WINTEC_CORP | G3: EM1000/1100 | H3: 3 | J3: PVDF | K3: EA | L3: 5184000 | N3: 물가자료25년9월호862page | O3: TRUE | P3: 전자유량계 | Q3: 3A | R3: 전자유량계 EM1000/1100
B4: =D4&"_"&F4&"_"&H4 -> I_FLM01_VM_WINTEC_CORP_5 | C4: 전자식 유량계 | D4: {=INDEX(계측기코드!$D$4:$D$189,MATCH(1,(C4=계측기코드!$F$4:$F$190)*1,0))} -> I_FLM01 | E4: 윈텍 | F4: {=INDEX(공급업체코드!$B$66:$B$150,MATCH(1,(E4=공급업체코드!$D$66:$D$150)*1,0))} -> VM_WINTEC_CORP | G4: EM1000/1100 | H4: 5 | J4: PVDF | K4: EA | L4: 5184000 | N4: 물가자료25년9월호862page | O4: TRUE | P4: 전자유량계 | Q4: 5A | R4: 전자유량계 EM1000/1100
B5: =D5&"_"&F5&"_"&H5 -> I_FLM01_VM_WINTEC_CORP_10 | C5: 전자식 유량계 | D5: {=INDEX(계측기코드!$D$4:$D$189,MATCH(1,(C5=계측기코드!$F$4:$F$190)*1,0))} -> I_FLM01 | E5: 윈텍 | F5: {=INDEX(공급업체코드!$B$66:$B$150,MATCH(1,(E5=공급업체코드!$D$66:$D$150)*1,0))} -> VM_WINTEC_CORP | G5: EM1000/1100 | H5: 10 | J5: PVDF | K5: EA | L5: 5184000 | N5: 물가자료25년9월호862page | O5: TRUE | P5: 전자유량계 | Q5: 10A | R5: 전자유량계 EM1000/1100
A6: 전자식 유량계, 15A | B6: =D6&"_"&F6&"_"&H6 -> I_FLM01_VM_WINTEC_CORP_15 | C6: 전자식 유량계 | D6: {=INDEX(계측기코드!$D$4:$D$189,MATCH(1,(C6=계측기코드!$F$4:$F$190)*1,0))} -> I_FLM01 | E6: 윈텍 | F6: {=INDEX(공급업체코드!$B$66:$B$150,MATCH(1,(E6=공급업체코드!$D$66:$D$150)*1,0))} -> VM_WINTEC_CORP | G6: EM1000/1100 | H6: 15 | J6: PVDF | K6: EA | L6: 3942000 | N6: 물가자료25년9월호862page | O6: TRUE | P6: 전자유량계 | Q6: 15A | R6: 전자유량계 EM1000/1100
B7: =D7&"_"&F7&"_"&H7 -> I_FLM01_VM_WINTEC_CORP_20 | C7: 전자식 유량계 | D7: {=INDEX(계측기코드!$D$4:$D$189,MATCH(1,(C7=계측기코드!$F$4:$F$190)*1,0))} -> I_FLM01 | E7: 윈텍 | F7: {=INDEX(공급업체코드!$B$66:$B$150,MATCH(1,(E7=공급업체코드!$D$66:$D$150)*1,0))} -> VM_WINTEC_CORP | G7: EM1000/1100 | H7: 20 | J7: PVDF | K7: EA | L7: 3942000 | N7: 물가자료25년9월호862page | O7: TRUE | P7: 전자유량계 | Q7: 20A | R7: 전자유량계 EM1000/1100
A8: 전자식 유량계, 25A | B8: =D8&"_"&F8&"_"&H8 -> I_FLM01_VM_WINTEC_CORP_25 | C8: 전자식 유량계 | D8: {=INDEX(계측기코드!$D$4:$D$189,MATCH(1,(C8=계측기코드!$F$4:$F$190)*1,0))} -> I_FLM01 | E8: 윈텍 | F8: {=INDEX(공급업체코드!$B$66:$B$150,MATCH(1,(E8=공급업체코드!$D$66:$D$150)*1,0))} -> VM_WINTEC_CORP | G8: EM1000/1100 | H8: 25 | J8: PVDF | K8: EA | L8: 3942000 | N8: 물가자료25년9월호862page | O8: TRUE | P8: 전자유량계 | Q8: 25A | R8: 전자유량계 EM1000/1100
A9: 전자식 유량계, 32A | B9: =D9&"_"&F9&"_"&H9 -> I_FLM01_VM_WINTEC_CORP_32 | C9: 전자식 유량계 | D9: {=INDEX(계측기코드!$D$4:$D$189,MATCH(1,(C9=계측기코드!$F$4:$F$190)*1,0))} -> I_FLM01 | E9: 윈텍 | F9: {=INDEX(공급업체코드!$B$66:$B$150,MATCH(1,(E9=공급업체코드!$D$66:$D$150)*1,0))} -> VM_WINTEC_CORP | G9: EM1000/1100 | H9: 32 | J9: PVDF | K9: EA | L9: 3942000 | N9: 물가자료25년9월호862page | O9: TRUE | P9: 전자유량계 | Q9: 32A | R9: 전자유량계 EM1000/1100
A10: 전자식 유량계, 40A | B10: =D10&"_"&F10&"_"&H10 -> I_FLM01_VM_WINTEC_CORP_40 | C10: 전자식 유량계 | D10: {=INDEX(계측기코드!$D$4:$D$189,MATCH(1,(C10=계측기코드!$F$4:$F$190)*1,0))} -> I_FLM01 | E10: 윈텍 | F10: {=INDEX(공급업체코드!$B$66:$B$150,MATCH(1,(E10=공급업체코드!$D$66:$D$150)*1,0))} -> VM_WINTEC_CORP | G10: EM1000/1100 | H10: 40 | J10: PVDF | K10: EA | L10: 3942000 | N10: 물가자료25년9월호862page | O10: TRUE | P10: 전자유량계 | Q10: 40A | R10: 전자유량계 EM1000/1100
A11: 전자식 유량계, 50A | B11: =D11&"_"&F11&"_"&H11 -> I_FLM01_VM_WINTEC_CORP_50 | C11: 전자식 유량계 | D11: {=INDEX(계측기코드!$D$4:$D$189,MATCH(1,(C11=계측기코드!$F$4:$F$190)*1,0))} -> I_FLM01 | E11: 윈텍 | F11: {=INDEX(공급업체코드!$B$66:$B$150,MATCH(1,(E11=공급업체코드!$D$66:$D$150)*1,0))} -> VM_WINTEC_CORP | G11: EM1000/1100 | H11: 50 | J11: PVDF | K11: EA | L11: 4140000 | N11: 물가자료25년9월호862page | O11: TRUE | P11: 전자유량계 | Q11: 50A | R11: 전자유량계 EM1000/1100
A12: 전자식 유량계, 65A | B12: =D12&"_"&F12&"_"&H12 -> I_FLM01_VM_WINTEC_CORP_65 | C12: 전자식 유량계 | D12: {=INDEX(계측기코드!$D$4:$D$189,MATCH(1,(C12=계측기코드!$F$4:$F$190)*1,0))} -> I_FLM01 | E12: 윈텍 | F12: {=INDEX(공급업체코드!$B$66:$B$150,MATCH(1,(E12=공급업체코드!$D$66:$D$150)*1,0))} -> VM_WINTEC_CORP | G12: EM1000/1100 | H12: 65 | J12: PVDF | K12: EA | L12: 4356000 | N12: 물가자료25년9월호862page | O12: TRUE | P12: 전자유량계 | Q12: 65A | R12: 전자유량계 EM1000/1100
A13: 전자식 유량계, 80A | B13: =D13&"_"&F13&"_"&H13 -> I_FLM01_VM_WINTEC_CORP_80 | C13: 전자식 유량계 | D13: {=INDEX(계측기코드!$D$4:$D$189,MATCH(1,(C13=계측기코드!$F$4:$F$190)*1,0))} -> I_FLM01 | E13: 윈텍 | F13: {=INDEX(공급업체코드!$B$66:$B$150,MATCH(1,(E13=공급업체코드!$D$66:$D$150)*1,0))} -> VM_WINTEC_CORP | G13: EM1000/1100 | H13: 80 | J13: PVDF | K13: EA | L13: 4554000 | N13: 물가자료25년9월호862page | O13: TRUE | P13: 전자유량계 | Q13: 80A | R13: 전자유량계 EM1000/1100
A14: 전자식 유량계, 100A | B14: =D14&"_"&F14&"_"&H14 -> I_FLM01_VM_WINTEC_CORP_100 | C14: 전자식 유량계 | D14: {=INDEX(계측기코드!$D$4:$D$189,MATCH(1,(C14=계측기코드!$F$4:$F$190)*1,0))} -> I_FLM01 | E14: 윈텍 | F14: {=INDEX(공급업체코드!$B$66:$B$150,MATCH(1,(E14=공급업체코드!$D$66:$D$150)*1,0))} -> VM_WINTEC_CORP | G14: EM1000/1100 | H14: 100 | J14: PVDF | K14: EA | L14: 5184000 | N14: 물가자료25년9월호862page | O14: TRUE | P14: 전자유량계 | Q14: 100A | R14: 전자유량계 EM1000/1100
A15: 전자식 유량계, 125A | B15: =D15&"_"&F15&"_"&H15 -> I_FLM01_VM_WINTEC_CORP_125 | C15: 전자식 유량계 | D15: {=INDEX(계측기코드!$D$4:$D$189,MATCH(1,(C15=계측기코드!$F$4:$F$190)*1,0))} -> I_FLM01 | E15: 윈텍 | F15: {=INDEX(공급업체코드!$B$66:$B$150,MATCH(1,(E15=공급업체코드!$D$66:$D$150)*1,0))} -> VM_WINTEC_CORP | G15: EM1000/1100 | H15: 125 | J15: EBONITE | K15: EA | L15: 5796000 | N15: 물가자료25년9월호862page | O15: TRUE | P15: 전자유량계 | Q15: 125A | R15: 전자유량계 EM1000/1100
A16: 전자식 유량계, 150A | B16: =D16&"_"&F16&"_"&H16 -> I_FLM01_VM_WINTEC_CORP_150 | C16: 전자식 유량계 | D16: {=INDEX(계측기코드!$D$4:$D$189,MATCH(1,(C16=계측기코드!$F$4:$F$190)*1,0))} -> I_FLM01 | E16: 윈텍 | F16: {=INDEX(공급업체코드!$B$66:$B$150,MATCH(1,(E16=공급업체코드!$D$66:$D$150)*1,0))} -> VM_WINTEC_CORP | G16: EM1000/1100 | H16: 150 | J16: EBONITE | K16: EA | L16: 6012000 | N16: 물가자료25년9월호862page | O16: TRUE | P16: 전자유량계 | Q16: 150A | R16: 전자유량계 EM1000/1100
A17: 전자식 유량계, 200A | B17: =D17&"_"&F17&"_"&H17 -> I_FLM01_VM_WINTEC_CORP_200 | C17: 전자식 유량계 | D17: {=INDEX(계측기코드!$D$4:$D$189,MATCH(1,(C17=계측기코드!$F$4:$F$190)*1,0))} -> I_FLM01 | E17: 윈텍 | F17: {=INDEX(공급업체코드!$B$66:$B$150,MATCH(1,(E17=공급업체코드!$D$66:$D$150)*1,0))} -> VM_WINTEC_CORP | G17: EM1000/1100 | H17: 200 | J17: EBONITE | K17: EA | L17: 6624000 | N17: 물가자료25년9월호862page | O17: TRUE | P17: 전자유량계 | Q17: 200A | R17: 전자유량계 EM1000/1100
A18: 전자식 유량계, 250A | B18: =D18&"_"&F18&"_"&H18 -> I_FLM01_VM_WINTEC_CORP_250 | C18: 전자식 유량계 | D18: {=INDEX(계측기코드!$D$4:$D$189,MATCH(1,(C18=계측기코드!$F$4:$F$190)*1,0))} -> I_FLM01 | E18: 윈텍 | F18: {=INDEX(공급업체코드!$B$66:$B$150,MATCH(1,(E18=공급업체코드!$D$66:$D$150)*1,0))} -> VM_WINTEC_CORP | G18: EM1000/1100 | H18: 250 | J18: EBONITE | K18: EA | L18: 7254000 | N18: 물가자료25년9월호862page | O18: TRUE | P18: 전자유량계 | Q18: 250A | R18: 전자유량계 EM1000/1100
A19: 전자식 유량계, 300A | B19: =D19&"_"&F19&"_"&H19 -> I_FLM01_VM_WINTEC_CORP_300 | C19: 전자식 유량계 | D19: {=INDEX(계측기코드!$D$4:$D$189,MATCH(1,(C19=계측기코드!$F$4:$F$190)*1,0))} -> I_FLM01 | E19: 윈텍 | F19: {=INDEX(공급업체코드!$B$66:$B$150,MATCH(1,(E19=공급업체코드!$D$66:$D$150)*1,0))} -> VM_WINTEC_CORP | G19: EM1000/1100 | H19: 300 | J19: EBONITE | K19: EA | L19: 7866000 | N19: 물가자료25년9월호862page | O19: TRUE | P19: 전자유량계 | Q19: 300A | R19: 전자유량계 EM1000/1100
... A25: 전자식 유량계, 700A | B25: =D25&"_"&F25&"_"&H25 -> I_FLM01_VM_WINTEC_CORP_700 | C25: 전자식 유량계 | D25: {=INDEX(계측기코드!$D$4:$D$189,MATCH(1,(C25=계측기코드!$F$4:$F$190)*1,0))} -> I_FLM01 | E25: 윈텍 | F25: {=INDEX(공급업체코드!$B$66:$B$150,MATCH(1,(E25=공급업체코드!$D$66:$D$150)*1,0))} -> VM_WINTEC_CORP | G25: EM1000/1100 | H25: 700 | J25: EBONITE | K25: EA | L25: 16776000 | N25: 물가자료25년9월호862page | O25: TRUE | P25: 전자유량계 | Q25: 700A | R25: 전자유량계 EM1000/1100
B26: =D26&"_"&F26&"_"&H26 -> I_FLM05_VM_HITROL_CO_100 | C26: 차압식 유량계 | D26: {=INDEX(계측기코드!$D$4:$D$189,MATCH(1,(C26=계측기코드!$F$4:$F$190)*1,0))} -> I_FLM05 | E26: 하이트롤 | F26: {=INDEX(공급업체코드!$B$66:$B$150,MATCH(1,(E26=공급업체코드!$D$66:$D$150)*1,0))} -> VM_HITROL_CO | G26: HFV-0100 | H26: 100 | K26: EA | L26: 7220000 | N26: 물가자료25년9월호861page | O26: TRUE | P26: 차압유량계 | R26: 차압식 Venturi Cone Meter HFV-0100
B27: =D27&"_"&F27&"_"&H27 -> I_FLM05_VM_HITROL_CO_200 | C27: 차압식 유량계 | D27: {=INDEX(계측기코드!$D$4:$D$189,MATCH(1,(C27=계측기코드!$F$4:$F$190)*1,0))} -> I_FLM05 | E27: 하이트롤 | F27: {=INDEX(공급업체코드!$B$66:$B$150,MATCH(1,(E27=공급업체코드!$D$66:$D$150)*1,0))} -> VM_HITROL_CO | G27: HFV-0200 | H27: 200 | K27: EA | L27: 12670000 | N27: 물가자료25년9월호861page | O27: TRUE | P27: 차압유량계 | R27: 차압식 Venturi Cone Meter HFV-0200
B28: =D28&"_"&F28&"_"&H28 -> I_FLM05_VM_HITROL_CO_250 | C28: 차압식 유량계 | D28: {=INDEX(계측기코드!$D$4:$D$189,MATCH(1,(C28=계측기코드!$F$4:$F$190)*1,0))} -> I_FLM05 | E28: 하이트롤 | F28: {=INDEX(공급업체코드!$B$66:$B$150,MATCH(1,(E28=공급업체코드!$D$66:$D$150)*1,0))} -> VM_HITROL_CO | G28: HFV-0250 | H28: 250 | K28: EA | L28: 14230000 | N28: 물가자료25년9월호861page | O28: TRUE | P28: 차압유량계 | R28: 차압식 Venturi Cone Meter HFV-0250
B29: =D29&"_"&F29&"_"&H29 -> I_FLM05_VM_HITROL_CO_300 | C29: 차압식 유량계 | D29: {=INDEX(계측기코드!$D$4:$D$189,MATCH(1,(C29=계측기코드!$F$4:$F$190)*1,0))} -> I_FLM05 | E29: 하이트롤 | F29: {=INDEX(공급업체코드!$B$66:$B$150,MATCH(1,(E29=공급업체코드!$D$66:$D$150)*1,0))} -> VM_HITROL_CO | G29: HFV-0300 | H29: 300 | K29: EA | L29: 18400000 | N29: 물가자료25년9월호861page | O29: TRUE | P29: 차압유량계 | R29: 차압식 Venturi Cone Meter HFV-0300
B30: =D30&"_"&F30&"_"&H30 -> I_FLM05_VM_HITROL_CO_400 | C30: 차압식 유량계 | D30: {=INDEX(계측기코드!$D$4:$D$189,MATCH(1,(C30=계측기코드!$F$4:$F$190)*1,0))} -> I_FLM05 | E30: 하이트롤 | F30: {=INDEX(공급업체코드!$B$66:$B$150,MATCH(1,(E30=공급업체코드!$D$66:$D$150)*1,0))} -> VM_HITROL_CO | G30: HFV-0400 | H30: 400 | K30: EA | L30: 31460000 | N30: 물가자료25년9월호861page | O30: TRUE | P30: 차압유량계 | R30: 차압식 Venturi Cone Meter HFV-0400
B31: =D31&"_"&F31&"_"&H31 -> I_FLM05_VM_HITROL_CO_500 | C31: 차압식 유량계 | D31: {=INDEX(계측기코드!$D$4:$D$189,MATCH(1,(C31=계측기코드!$F$4:$F$190)*1,0))} -> I_FLM05 | E31: 하이트롤 | F31: {=INDEX(공급업체코드!$B$66:$B$150,MATCH(1,(E31=공급업체코드!$D$66:$D$150)*1,0))} -> VM_HITROL_CO | G31: HFV-0500 | H31: 500 | K31: EA | L31: 40300000 | N31: 물가자료25년9월호861page | O31: TRUE | P31: 차압유량계 | R31: 차압식 Venturi Cone Meter HFV-0500
B32: =D32&"_"&F32&"_"&H32 -> I_FLM05_VM_HITROL_CO_600 | C32: 차압식 유량계 | D32: {=INDEX(계측기코드!$D$4:$D$189,MATCH(1,(C32=계측기코드!$F$4:$F$190)*1,0))} -> I_FLM05 | E32: 하이트롤 | F32: {=INDEX(공급업체코드!$B$66:$B$150,MATCH(1,(E32=공급업체코드!$D$66:$D$150)*1,0))} -> VM_HITROL_CO | G32: HFV-0600 | H32: 600 | K32: EA | L32: 47800000 | N32: 물가자료25년9월호861page | O32: TRUE | P32: 차압유량계 | R32: 차압식 Venturi Cone Meter HFV-0600
B33: =D33&"_"&F33&"_"&H33 -> I_FLM05_VM_HITROL_CO_700 | C33: 차압식 유량계 | D33: {=INDEX(계측기코드!$D$4:$D$189,MATCH(1,(C33=계측기코드!$F$4:$F$190)*1,0))} -> I_FLM05 | E33: 하이트롤 | F33: {=INDEX(공급업체코드!$B$66:$B$150,MATCH(1,(E33=공급업체코드!$D$66:$D$150)*1,0))} -> VM_HITROL_CO | G33: HFV-0700 | H33: 700 | K33: EA | L33: 59900000 | N33: 물가자료25년9월호861page | O33: TRUE | P33: 차압유량계 | R33: 차압식 Venturi Cone Meter HFV-0700
B34: =D34&"_"&F34&"_"&H34 -> I_FLM05_VM_HITROL_CO_800 | C34: 차압식 유량계 | D34: {=INDEX(계측기코드!$D$4:$D$189,MATCH(1,(C34=계측기코드!$F$4:$F$190)*1,0))} -> I_FLM05 | E34: 하이트롤 | F34: {=INDEX(공급업체코드!$B$66:$B$150,MATCH(1,(E34=공급업체코드!$D$66:$D$150)*1,0))} -> VM_HITROL_CO | G34: HFV-0800 | H34: 800 | K34: EA | L34: 72000000 | N34: 물가자료25년9월호861page | O34: TRUE | P34: 차압유량계 | R34: 차압식 Venturi Cone Meter HFV-0800

Sheet pH측정기
B1: 장비코드 | D1: 장비유형 | H1: 보호등급 | I1: 접액부재질 | J1: 단위 | K1: 단가(원) | L1: 견적가(원) | M1: 단가출처 | N1: 사용여부 | O1: 품명 | P1: 규격 | Q1: 장비설명 | R1: 단위시스템코드
B2: equipment_code | C2: 작업용 필드 | D2: equipment_type | E2: 작업용 필드 | F2: vendor_id | G2: model_number | H2: s_ingress_protection_NONE | I2: s_wettedpart_material_NONE | J2: s_unit_NONE | K2: o_unit_price_KRW | L2: o_invoice_price_KRW | M2: o_price_reference | N2: is_active | O2: s_productnm_NONE | P2: s_easpecific_NONE | Q2: description | R2: unit_system_code
B3: =D3&"_"&F3 -> I_PHM01_VM_NANO_HITECH | C3: 유리전극식 pH측정기 | D3: {=INDEX(계측기코드!$D$4:$D$189,MATCH(1,(C3=계측기코드!$F$4:$F$190)*1,0))} -> I_PHM01 | E3: 나노하이텍 | F3: {=INDEX(공급업체코드!$B$66:$B$150,MATCH(1,(E3=공급업체코드!$D$66:$D$150)*1,0))} -> VM_NANO_HITECH | G3: nanoCHEM3000 | J3: EA | K3: 4500000 | M3: 물가자료25년9월호 1040page | N3: TRUE | O3: =C3 -> 유리전극식 pH측정기 | Q3: 유리복합전극 수소이온농도(pH) 측정기 nanoCHEM3000

Sheet ORP측정기
B1: 장비코드 | D1: 장비유형 | H1: 보호등급 | I1: 접액부재질 | J1: 단위 | K1: 단가(원) | L1: 견적가(원) | M1: 단가출처 | N1: 사용여부 | O1: 품명 | P1: 규격 | Q1: 장비설명 | R1: 단위시스템코드
B2: equipment_code | C2: 작업용 필드 | D2: equipment_type | E2: 작업용 필드 | F2: vendor_id | G2: model_number | H2: s_ingress_protection_NONE | I2: s_wettedpart_material_NONE | J2: s_unit_NONE | K2: o_unit_price_KRW | L2: o_invoice_price_KRW | M2: o_price_reference | N2: is_active | O2: s_productnm_NONE | P2: s_easpecific_NONE | Q2: description | R2: unit_system_code
B3: =D3&"_"&F3 -> I_ORP01_VM_NANO_HITECH | C3: 금속전극식 ORP 측정기 | D3: {=INDEX(계측기코드!$D$4:$D$189,MATCH(1,(C3=계측기코드!$F$4:$F$190)*1,0))} -> I_ORP01 | E3: 나노하이텍 | F3: {=INDEX(공급업체코드!$B$66:$B$150,MATCH(1,(E3=공급업체코드!$D$66:$D$150)*1,0))} -> VM_NANO_HITECH | G3: nanoCHEM3000 | J3: EA | K3: 4500000 | M3: 물가자료25년9월호 1040page | N3: TRUE | O3: =C3 -> 금속전극식 ORP 측정기 | Q3: 금속복합전극 산화전위차 (ORP) 측정기 nanoCHEM3000

Sheet DO 측정기
C1: 장비코드 | D1: 장비유형 | G1: 모델명 (품명) | H1: 보호등급 | I1: 접액부재질 | J1: 단위 | K1: 단가(원) | L1: 견적가(원) | M1: 단가출처 | N1: 사용여부 | O1: 품명 | P1: 규격 | Q1: 장비설명 | R1: 단위시스템코드
B2: equipment_code | C2: 작업용 필드 | D2: equipment_type | E2: 작업용 필드 | F2: vendor_id | G2: model_number | H2: s_ingress_protection_NONE | I2: s_wettedpart_material_NONE | J2: s_unit_NONE | K2: o_unit_price_KRW | L2: o_invoice_price_KRW | M2: o_price_reference | N2: is_active | O2: s_productnm_NONE | P2: s_easpecific_NONE | Q2: description | R2: unit_system_code
B3: =D3&"_"&F3 -> I_DOM01_VM_NANO_HITECH | C3: 광학식 DO 측정기 | D3: {=INDEX(계측기코드!$D$4:$D$189,MATCH(1,(C3=계측기코드!$F$4:$F$190)*1,0))} -> I_DOM01 | E3: 나노하이텍 | F3: {=INDEX(공급업체코드!$B$66:$B$150,MATCH(1,(E3=공급업체코드!$D$66:$D$150)*1,0))} -> VM_NANO_HITECH | G3: nanoCHEM9000 | J3: EA | K3: 10000000 | M3: 물가자료25년9월호 862page | N3: TRUE | O3: =C3 -> 광학식 DO 측정기 | Q3: 용존산소계(DO) 수질계측기(현장설치용) nanoCHEM9000, 광학식

Sheet 압력계
B1: 장비코드 | D1: 장비유형 | G1: 모델명 | H1: 최대 측정 압력 (bar) | I1: 보호등급 | J1: 접액부재질 | K1: 단위 | L1: 단가(원) | M1: 견적가(원) | N1: 단가출처 | O1: 사용여부 | P1: 품명 | Q1: 규격 | S1: 단위시스템코드
A2: 3D모델 유형명 | B2: equipment_code | C2: 작업용 필드 | D2: equipment_type | E2: 작업용 필드 | F2: vendor_id | G2: model_number | H2: i_max_meas_press_bar | I2: s_ingress_protection_NONE | J2: s_wettedpart_material_NONE | K2: s_unit_NONE | L2: o_unit_price_KRW | M2: o_invoice_price_KRW | N2: o_price_reference | O2: is_active | P2: s_productnm_NONE | Q2: s_easpecific_NONE | R2: description | S2: unit_system_code
A3: 압력계 | B3: =D3&"_"&F3&"_"&H3 -> I_PRSS02_VM_BACKKWANG_IST_25 | C3: 격막식 압력계 | D3: {=INDEX(계측기코드!$D$4:$D$189,MATCH(1,(C3=계측기코드!$F$4:$F$190)*1,0))} -> I_PRSS02 | E3: 백광아이에스티 | F3: {=INDEX(공급업체코드!$B$66:$B$150,MATCH(1,(E3=공급업체코드!$D$66:$D$150)*1,0))} -> VM_BACKKWANG_IST | H3: 25 | K3: EA | L3: 1200000 | N3: 물가자료25년9월호996page | O3: TRUE | P3: 격막식압력계 | Q3: 15A | R3: 격막식압력계 2.5Mpa/탄탈륨

Sheet 온도계
C1: 장비코드 | D1: 장비유형 | G1: 모델명 | H1: 보호등급 | I1: 접액부재질 | J1: 단위 | K1: 단가(원) | L1: 견적가(원) | M1: 단가출처 | N1: 사용여부 | O1: 품명 | P1: 규격 | R1: 단위시스템코드
B2: equipment_code | C2: 작업용 필드 | D2: equipment_type | E2: 작업용 필드 | F2: vendor_id | G2: model_number | H2: s_ingress_protection_NONE | I2: s_wettedpart_material_NONE | J2: s_unit_NONE | K2: o_unit_price_KRW | L2: o_invoice_price_KRW | M2: o_price_reference | N2: is_active | O2: s_productnm_NONE | P2: s_easpecific_NONE | Q2: description | R2: unit_system_code
B3: =D3&"_"&F3 -> I_THM00_VM_0000 | C3: 미분류 온도계 | D3: {=INDEX(계측기코드!$D$4:$D$189,MATCH(1,(C3=계측기코드!$F$4:$F$190)*1,0))} -> I_THM00 | E3: 미지정업체 | F3: {=INDEX(공급업체코드!$B$3:$B$150,MATCH(1,(E3=공급업체코드!$D$3:$D$150)*1,0))} -> VM_0000 | J3: EA | K3: 0 | N3: TRUE | O3: pH계(온도) | Q3: pH계(온도)
B4: =D4&"_"&F4 -> I_THM01_VM_HITROL_CO | C4: RTD식 온도계 | D4: {=INDEX(계측기코드!$D$4:$D$189,MATCH(1,(C4=계측기코드!$F$4:$F$190)*1,0))} -> I_THM01 | E4: 하이트롤 | F4: {=INDEX(공급업체코드!$B$66:$B$150,MATCH(1,(E4=공급업체코드!$D$66:$D$150)*1,0))} -> VM_HITROL_CO | J4: EA | K4: 1060000 | M4: 물가자료25년9월호861page | N4: TRUE | O4: =C4 -> RTD식 온도계 | Q4: Pt 100 ohm, L=150mm

Sheet MLSS계
C1: 장비코드 | D1: 장비유형 | G1: 모델명 | H1: 보호등급 | I1: 접액부재질 | J1: 단위 | K1: 단가(원) | L1: 견적가(원) | M1: 단가출처 | N1: 사용여부 | O1: 품명 | P1: 규격 | R1: 단위시스템코드
B2: equipment_code | C2: 작업용 필드 | D2: equipment_type | E2: 작업용 필드 | F2: vendor_id | G2: model_number | H2: s_ingress_protection_NONE | I2: s_wettedpart_material_NONE | J2: s_unit_NONE | K2: o_unit_price_KRW | L2: o_invoice_price_KRW | M2: o_price_reference | N2: is_active | O2: s_productnm_NONE | P2: s_easpecific_NONE | Q2: description | R2: unit_system_code
B3: =D3&"_"&F3 -> I_MLS02_VM_NANO_HITECH | C3: 적외선 MLSS계 | D3: {=INDEX(계측기코드!$D$4:$D$189,MATCH(1,(C3=계측기코드!$F$4:$F$190)*1,0))} -> I_MLS02 | E3: 나노하이텍 | F3: VM_NANO_HITECH | G3: NanoCHEM 7000 | J3: EA | K3: 11000000 | M3: 물가자료25년9월호 1040page | N3: TRUE | O3: =C3 -> 적외선 MLSS계 | Q3: 혼합부유물농도(MLSS)측정기
